Workbook

Sheet 表紙
C2: 厚生系統合システム
C6: 外部機能仕様（機能別）
Q11: 構成管理番号 | AC11: KSED-JHA02
Q15: 業務名 | AC15: 住宅補助費
Q19: 機能ＩＤ | AC19: JHA02
Q23: 機能名 | AC23: 住宅補助費支給額一括アップロード

Sheet 変更内容一覧
C2: 厚生系統合システム | AI2: 外部機能仕様（機能別）
AD6: 変更内容一覧
C9: 機能ＩＤ | H9: =表紙!AC19 -> JHA02 | V9: 機能名 | AA9: =表紙!AC23 -> 住宅補助費支給額一括アップロード
C12: 管理番号 | L12: 版 | P12: 変更理由 | AH12: 変更内容 | AZ12: 変更箇所 | BJ12: 変更区分 | BO12: 作成者 ・日付
L14: 1.0 | P14: 新規 | BJ14: 更新 | BO14: 片桐 峻 2022/9/27
BJ15: 追加
BJ16: 削除
BJ17: 更新
BJ18: 追加
BJ19: 削除
BJ20: 更新
BJ21: 追加
BJ22: 削除
BJ23: 更新
BJ24: 追加
BJ25: 削除
BJ26: 更新
... BJ31: 削除

Sheet 機能概要
A1: 機能概要 | P1: 業 務 | T1: =表紙!AC15 -> 住宅補助費 | AH1: 機 能 | AL1: =表紙!AC23 -> 住宅補助費支給額一括アップロード | AZ1: 作成者 | BC1: 片桐 峻 | BJ1: 作成日 | BM1: 44831
P2: 処 理 | T2: 住宅補助費支給額一括アップロード | AH2: 処理種別 | AL2: オンバッチ | AZ2: 修正者 | BJ2: 修正日
B5: 機能概要 | AM5: データフロー
B6: 住宅補助費申請の支給額を変更したリスト（ＣＳＶ）を作成して一括登録する。
B22: 前提条件・制約事項・運用上の留意事項
B23: １．バッチ起動条件 【起動条件】 ：オンライン処理からの起動（複数回の起動を可能とする） 【処理周期】 ：随時 【起動パラメータ】：アップロードファイル名 【対象ファイル】 ：住宅補助費支給額補正ファイル（CSV） 【関連機能】 【前処理】 ：なし 【後処理】 ：一括登録・データ抽出結果照会 ■機能仕様 ・アップロードファイルは１ファイル毎とする ・圧縮ファイルは不可 ・拡張子はcsv
B37: セキュリティ要件
B38: ◆利用権限 BA社 各社厚生担当 ◆セキュリティ範囲 BA社：制限なし 各社厚生担当：自会社のみ

Sheet 画面遷移図
A1: 画面遷移図 | P1: 業 務 | T1: =表紙!AC15 -> 住宅補助費 | AH1: 機 能 | AL1: =表紙!AC23 -> 住宅補助費支給額一括アップロード | AZ1: 作成者 | BC1: =機能概要!BC1 -> 片桐 峻 | BJ1: 作成日 | BM1: =機能概要!BM1 -> 44831
P2: 処 理 | T2: =機能概要!T2 -> 住宅補助費支給額一括アップロード | AH2: 処理種別 | AL2: =機能概要!AL2 -> オンバッチ | AZ2: 修正者 | BJ2: 修正日

Sheet 画面レイアウト
A1: 画面レイアウト | P1: 業 務 | T1: =表紙!AC15 -> 住宅補助費 | AH1: 機 能 | AL1: =表紙!AC23 -> 住宅補助費支給額一括アップロード | AZ1: 作成者 | BC1: =機能概要!BC1 -> 片桐 峻 | BJ1: 作成日 | BM1: =機能概要!BM1 -> 44831
P2: 処 理 | T2: =機能概要!T2 -> 住宅補助費支給額一括アップロード | AH2: 処理種別 | AL2: =機能概要!AL2 -> オンバッチ | AZ2: 修正者 | BJ2: 修正日
C5: 画面名 | H5: 住宅補助費支給額一括アップロード画面（1/2） | T5: 表示名 | V5: 住宅補助費支給額一括アップロード | AH5: 画面ＩＤ | AM5: JHA02S01
C30: 画面名 | H30: 住宅補助費支給額一括アップロード画面（2/2） | T30: 表示名 | V30: 住宅補助費支給額一括アップロード | AH30: 画面ＩＤ | AM30: JHA02S01

Sheet 画面項目仕様
A1: 画面項目仕様 | P1: 業 務 | T1: =表紙!AC15 -> 住宅補助費 | AH1: 機 能 | AL1: =表紙!AC23 -> 住宅補助費支給額一括アップロード | AZ1: 作成者 | BC1: =機能概要!BC1 -> 片桐 峻 | BJ1: 作成日 | BM1: =機能概要!BM1 -> 44831
P2: 処 理 | T2: =機能概要!T2 -> 住宅補助費支給額一括アップロード | AH2: 処理種別 | AL2: =機能概要!AL2 -> オンバッチ | AZ2: 修正者 | BJ2: 修正日
C5: 画面名 | H5: 住宅補助費支給額一括アップロード画面 | T5: 表示名 | V5: 住宅補助費支給額一括アップロード | AH5: 画面ＩＤ | AM5: JHA02S01
C7: 項番 | E7: 画面項目名 | O7: 入力形式 | U7: 属性 | X7: 桁数 | AB7: 共通チェックID | AG7: 入出力 | AJ7: 必須 | AL7: 初期値 | AQ7: 英語 対応 | AS7: 編集仕様／処理概要
X8: 最小 | Z8: 最大
C9: 1 | E9: （ファイルアップロード） | O9: ファイル選択単一 | U9: － | X9: － | Z9: － | AG9: 入力 | AJ9: ○ | AS9: 【チェック用パラメータ】 ファイルサイズ上限：5MB 許容拡張子：csv ※共通外部機能仕様参照
C11: =C9+1 -> 2 | E11: 実行 | O11: ボタン | U11: － | X11: － | Z11: － | AB11: 登録チェック ファイルアップロードチェック | AG11: － | AS11: 「登録確認ダイアログ」を表示する。 「外部機能仕様（共通） 画面レイアウト」参照 【確認ダイアログパラメータ】 処理名：その他 その他文言：ファイルを登録してもよろしいですか？ ・初期表示では表示し、登録処理実行後は非表示にする。
C13: =C11+1 -> 3 | E13: 結果照会へ | O13: ボタン | U13: － | X13: － | Z13: － | AG13: － | AS13: 一括登録結果照会画面へ遷移する。 初期表示では非表示とし、登録処理実行後に表示する。

Sheet 機能詳細（オンライン）
A1: 機能詳細 | P1: 業 務 | T1: =表紙!AC15 -> 住宅補助費 | AH1: 機 能 | AL1: =表紙!AC23 -> 住宅補助費支給額一括アップロード | AZ1: 作成者 | BC1: =機能概要!BC1 -> 片桐 峻 | BJ1: 作成日 | BM1: =機能概要!BM1 -> 44831
P2: 処 理 | T2: =機能概要!T2 -> 住宅補助費支給額一括アップロード | AH2: 処理種別 | AL2: =機能概要!AL2 -> オンバッチ | AZ2: 修正者 | BJ2: 修正日
A4: 入力 | N4: 処理 | BC4: イベントID | BH4: 出力
O6: １．住宅補助費支給額一括アップロード画面
O7: （１）ファイル選択時
P8: ア．アップロード対象ファイルを選択する。
Q9: ※複数ファイルの選択は不可とする。
C10: 住宅補助費支給額一括アップロード画面
O11: （２）『実行』ボタン押下時
P12: ア．確認ダイアログを表示する。（「画面項目仕様」を参照）
P13: （ア）『はい』を選択した場合、以下の処理を実行する。
P14: ａ．確認ダイアログを閉じる。
C15: 〔住宅補助費支給額補正ファイル〕 | P15: ｂ．業務共通のアップロード機能を呼び出し、ファイルをアップロードする。
P16: ｃ．住宅補助費支給額一括アップロード（バッチ）の実行を依頼し依頼受付番号を取得する。
R17: 一括登録（ジョブ登録）（外部機能仕様（共通）機能詳細－一括登録（ジョブ登録）参照）
R18: （バッチ処理の内容については、「機能詳細（バッチ）」を参照）
P20: ｄ．住宅補助費支給額一括アップロード画面（結果）を表示する。
P21: （ａ）上記、ｃ． で取得した依頼受付番号を画面に表示する。（「チェック仕様 １．オンライン 項番01,02」を参照） | BK21: 〔住宅補助費支給額補正ファイル〕
P23: （イ）『いいえ』を選択した場合、確認ダイアログを閉じる。
O25: （３）『結果照会へ』ボタン押下時
P26: ア．一括登録・データ抽出結果照会画面へ遷移する。

Sheet 機能詳細(バッチ)
A1: 機能詳細 | P1: 業 務 | T1: =表紙!AC15 -> 住宅補助費 | AH1: 機 能 | AL1: =表紙!AC23 -> 住宅補助費支給額一括アップロード | AZ1: 作成者 | BC1: =機能概要!BC1 -> 片桐 峻 | BJ1: 作成日 | BM1: =機能概要!BM1 -> 44831
P2: 処 理 | T2: =機能概要!T2 -> 住宅補助費支給額一括アップロード | AH2: 処理種別 | AL2: =機能概要!AL2 -> オンバッチ | AZ2: 修正者 | BJ2: 修正日
A4: 入力 | N4: 処理 | BC4: イベントID | BH4: 出力
O6: １．初期処理
O7: （１）ＤＢのトランザクションの開始
O9: （２）処理開始
P10: ア．処理開始のメッセージを出力する。（「チェック仕様 ２．バッチ 項番01」を参照）
O12: （３）起動パラメータの取得
P13: ア．入力ファイル情報の取得
Q14: 入力ファイル情報（アップロードされたファイルパス）を取得する。
Q15: 入力ファイル情報が取得できない場合、エラーメッセージをログに取得し、処理を異常終了する。
Q16: （「チェック仕様 ２．バッチ 項番02」を参照）
O18: （４）入力ファイルのオープン
D19: 〔住宅補助費支給額補正ファイル〕 | P19: ア．〔住宅補助費支給額補正ファイル〕を開く。（「チェック仕様 ２．バッチ 項番04」を参照）
O21: （５）出力ファイル〔処理結果リスト〕へのヘッダ出力
P22: ア．〔処理結果リスト〕を開き、ヘッダ行を出力する。（「チェック仕様 バッチ 項番05」を参照）
Q23: （出力イメージは、「補足説明 ２．処理結果リストのイメージ」を参照）
O25: （６）出力ファイル〔エラーリスト〕へのヘッダ出力
P26: ア．〔エラーリスト〕を開き、ヘッダ行を出力する。（「チェック仕様 バッチ 項番05」を参照） | BK26: 〔処理結果リスト〕
Q27: （出力イメージは、「補足説明 ３．エラーリストのイメージ」を参照） | BK27: 〔エラーリスト〕
O30: ２．主処理
O31: （１）〔住宅補助費支給額補正ファイル〕より１レコードずつ読み込み、終了まで以下を繰り返す。
P32: 読み込み時に入力ファイルの項目数をチェックし、項目数がファイルレイアウト通りではない場合、
P33: 入力ファイルからの読込はそのレコードまでで終了する。（「チェック仕様 バッチ 項番15」を参照）
P34: （ファイルレイアウトは、「入力ファイル項目仕様」を参照）
D35: 〔住宅補助費支給額補正ファイル〕
P36: ア．入力ファイルの項目チェック
P37: （ア）バリデーションチェックを行う（入力ファイル項目仕様の属性、桁数、共通チェックID、必須のチェック）
Q38: （「外部機能仕様（共通）－バリデーションチェック」参照）
P39: （イ）重複レコードチェック（後勝ち）を行う
Q40: （「外部機能仕様（共通）機能詳細－一括登録(重複チェック)」参照）
D41: ［住宅補助費申請確定分］ | P41: （ウ）機能個別チェックを行う
Q42: （「チェック仕様 バッチ 項番07～09」を参照）
P44: イ．［住宅補助費申請確定分］の更新
P45: （ア）入力チェックでエラーが発生していない場合、氏名コード、借家番号、申請IDをキーにして、［住宅補助費申請確定分］の更新を行う。
Q46: （「テーブル更新仕様 住宅補助費申請確定分 更新」を参照）
BK47: ［住宅補助費申請確定分］
P48: カ．入力ファイルのレコード情報を、ファイルに出力する。
P49: （ア）入力チェックでエラーが発生していない場合
Q50: ａ．入力ファイルのレコード情報および、更新区分を〔処理結果リスト〕ファイルに出力する。
...

Sheet チェック仕様
A1: チェック仕様 | P1: 業 務 | T1: =表紙!AC15 -> 住宅補助費 | AH1: 機 能 | AL1: =表紙!AC23 -> 住宅補助費支給額一括アップロード | AZ1: 作成者 | BC1: =機能概要!BC1 -> 片桐 峻 | BJ1: 作成日 | BM1: =機能概要!BM1 -> 44831
P2: 処 理 | T2: =機能概要!T2 -> 住宅補助費支給額一括アップロード | AH2: 処理種別 | AL2: =機能概要!AL2 -> オンバッチ | AZ2: 修正者 | BJ2: 修正日
B5: １．オンライン
B6: 項番 | D6: チェック項目 | J6: チェック内容 | X6: チェック契機 | AD6: 出力先 | AH6: 重要度 | AL6: メッセージID | AQ6: メッセージテキスト | BH6: 埋込情報 | BR6: 英語 対応
B8: 01 | D8: － | J8: － | X8: 処理完了時 | AD8: メッセージ出力エリア | AH8: メッセージ | AL8: JHA02I001 | AQ8: 下記の受付番号で登録しました。
B10: 02 | D10: － | J10: － | X10: 処理完了時 | AD10: メッセージ出力エリア | AH10: メッセージ | AL10: JHA02I002 | AQ10: [依頼受付番号:%1] | BH10: %1:[依頼受付番号]
B14: ２．バッチ
B15: 項番 | D15: チェック項目 | J15: チェック内容 | X15: チェック契機 | AD15: 出力先 | AH15: 重要度 | AL15: メッセージID | AQ15: メッセージテキスト | BH15: 埋込情報 | BR15: 英語 対応
B17: 01 | D17: 開始ログ | J17: － | X17: 処理開始時 | AD17: ＡＰログ | AH17: メッセージ | AL17: SSB00I001 | AQ17: %1 処理開始 | BH17: %1:“住宅補助費支給額一括アップロード”
B20: 02 | D20: 入力パラメータ | J20: － | X20: 処理開始時 | AD20: ＡＰログ | AH20: 異常 | AL20: JHA02E001 | AQ20: 起動パラメータ取得でエラーが発生しました。[起動パラメータ：%1] | BH20: %1:“起動パラメータ”
B23: 03 | D23: ファイル名表示 | J23: － | X23: 処理開始時 | AD23: ＡＰログ | AH23: メッセージ | AL23: JHA02I003 | AQ23: 入力ファイル:%1 | BH23: %1:入力ファイルパス名
B26: 04 | D26: ファイルオープン | J26: ファイルがオープンできること。 （処理中断） | X26: ファイルオープン時 | AD26: ＡＰログ | AH26: 異常 | AL26: SSB00E003 | AQ26: ファイルオープン時にエラーが発生しました。[ファイル:%1] | BH26: %1:入力ファイルパス名
B29: 05 | D29: ファイル出力 | J29: ファイル書込みできること。 （処理中断） | X29: ファイル読込時 | AD29: ＡＰログ | AH29: 異常 | AL29: SSB00E008 | AQ29: ファイル出力時にエラーが発生しました。[ファイル:%1] | BH29: %1:出力ファイルパス名
B32: 06 | D32: ファイル読込 | J32: 〔住宅補助費支給額補正ファイル〕が読み込みできること。（処理中断） | X32: 〔住宅補助費支給額補正ファイル〕読み込み時 | AD32: ＡＰログ | AH32: 異常 | AL32: JHA02E002 | AQ32: ファイル入力時にエラーが発生しました。[ファイル:%1] | BH32: %1:入力ファイルパス名
B35: 07 | D35: 氏名コード、借家番号、申請ID | J35: 住宅補助費申請確定分に存在すること。 | X35: 項目チェック時 | AD35: エラーリスト | AH35: エラー | AL35: JHA02E003 | AQ35: 住宅補助申請が承認されていません。
B38: 08 | D38: 氏名コード | J38: セキュリティ範囲内の氏名コードであること。 | X38: 項目チェック時 | AD38: エラーリスト | AH38: エラー | AL38: JHA02E004 | AQ38: 氏名コードがセキュリティ範囲内ではありません。[氏名コード:%1] | BH38: %1:氏名コード
B41: 09 | D41: ファイルクローズ | J41: ファイルがクローズできること。（処理中断） | X41: ファイルクローズ時 | AD41: ＡＰログ | AH41: 異常 | AL41: SSB00E004 | AQ41: ファイルクローズ時にエラーが発生しました。[ファイル:%1] | BH41: %1:入力ファイルパス名
B44: 10 | D44: 入力件数表示 | J44: － | X44: 処理終了時 | AD44: ＡＰログ | AH44: メッセージ | AL44: JHA02I004 | AQ44: [ファイル:%1] 入力件数:%2 | BH44: %1:“住宅補助費支給額補正ファイル” %2:〔住宅補助費支給額補正ファイル〕の入力件数
B48: 11 | D48: 出力件数表示（処理結果リスト） | J48: － | X48: 処理終了時 | AD48: ＡＰログ | AH48: メッセージ | AL48: JHA02I005 | AQ48: [ファイル:%1] 出力件数:%2 | BH48: %1:“処理結果リスト” %2:〔処理結果リスト〕の出力件数
B52: 12 | D52: 出力件数表示（エラーリスト） | J52: － | X52: 処理終了時 | AD52: ＡＰログ | AH52: メッセージ | AL52: JHA02I006 | AQ52: [ファイル:%1] 出力件数:%2 | BH52: %1:“エラーリスト” %2:〔エラーリスト〕の出力件数
B56: 13 | D56: 更新結果表示 | J56: － | X56: 処理終了時 | AD56: ＡＰログ | AH56: メッセージ | AL56: JHA02I007 | AQ56: [テーブル:%1] 更新件数:%2 | BH56: %1:“住宅補助費申請確定分” %2:[住宅補助費申請確定分]の更新件数
B59: 14 | D59: 終了 | J59: － | X59: 処理終了時 | AD59: ＡＰログ | AH59: メッセージ | AL59: SSB00I002 | AQ59: %1 処理終了 | BH59: %1:“住宅補助費支給額一括アップロード”
B62: 15 | D62: 項目数 | J62: 入力ファイルの項目数が入力ファイル項目仕様通りであること。（処理継続） | X62: 入力ファイル読込時 | AD62: エラーリスト | AH62: エラー | AL62: SSB02E004 | AQ62: フォーマットエラーです。フォーマットを確認してください。[行番号:%1] | BH62: %1:行番号

Sheet 入力ファイル項目仕様
A1: 入力ファイル項目仕様 | P1: 業 務 | T1: =表紙!AC15 -> 住宅補助費 | AH1: 機 能 | AL1: =表紙!AC23 -> 住宅補助費支給額一括アップロード | AZ1: 作成者 | BC1: =機能概要!BC1 -> 片桐 峻 | BJ1: 作成日 | BM1: =機能概要!BM1 -> 44831
P2: 処 理 | T2: =機能概要!T2 -> 住宅補助費支給額一括アップロード | AH2: 処理種別 | AL2: =機能概要!AL2 -> オンバッチ | AZ2: 修正者 | BJ2: 修正日
C5: 日本語ファイル名 | J5: 住宅補助費支給額補正ファイル | AH5: ファイルＩＤ | AM5: JHA02F01
C7: ファイル形式 | L7: レコード形式 | Q7: レコード長 | V7: ファイル名
C9: ＣＳＶ形式 | L9: 可変長 | Q9: － | V9: 1234567_JHA02F01_20200805105600000.csv （氏名コード ＋ _ ＋ ファイルID ＋ _ ＋ 作成時刻 ＋ 拡張子）
C11: 入力ファイル説明
C12: 既に住宅補助申請が承認された社員の適用年月、支給金額を修正する為のアップロードファイル。
C15: その他
C16: CSVは以下の形式で作成すること ・文字コード：Windows-31J(CP932) ・改行コード:<CR><LF> ・区切り文字:","（ダブルクォーテーション有り） ・カラム：“”ダブルクォーテーションは、許容しない。 先頭行は、ヘッダレコードとして、読み飛ばす。
C22: ※出力イメージは「補足説明 １．住宅補助費支給額補正ファイルのイメージ」を参照
C24: データレコード
C25: 項番 | F25: 項目名 | T25: 属性 | W25: 桁数 | AA25: 共通チェックID | AF25: 必須 | AH25: 項目説明
W26: 最小 | Y26: 最大
C27: 01 | F27: 氏名コード | T27: X | W27: 7 | Y27: 7 | AF27: ○ | AH27: 氏名コードを設定する。
C29: 02 | F29: 借家番号 | T29: X | W29: 1 | Y29: 1 | AF29: ○ | AH29: 借家番号を設定する。
C31: 03 | F31: 申請ID | T31: X | W31: 16 | Y31: 16 | AF31: ○ | AH31: 申請IDを設定する。
C33: 04 | F33: 支給額 | T33: 9 | W33: 1 | Y33: 6 | AF33: ○ | AH33: 支給額を設定する。
C35: 05 | F35: 適用年月 | T35: 日付 | W35: 6 | Y35: 6 | AF35: ○ | AH35: 対象年度を設定する。（YYYYMM）

Sheet 出力ファイル項目仕様（処理結果リスト）
A1: 出力ファイル項目仕様 | P1: 業 務 | T1: =表紙!AC15 -> 住宅補助費 | AH1: 機 能 | AL1: =表紙!AC23 -> 住宅補助費支給額一括アップロード | AZ1: 作成者 | BC1: =機能概要!BC1 -> 片桐 峻 | BJ1: 作成日 | BM1: =機能概要!BM1 -> 44831
P2: 処 理 | T2: =機能概要!T2 -> 住宅補助費支給額一括アップロード | AH2: 処理種別 | AL2: =機能概要!AL2 -> オンバッチ | AZ2: 修正者 | BJ2: 修正日
C5: 日本語ファイル名 | J5: 処理結果リスト | AH5: ファイルＩＤ | AM5: JHA02F02
C7: ファイル形式 | L7: レコード形式 | Q7: レコード長 | V7: ファイル名
C9: ＣＳＶ形式 | L9: 可変長 | Q9: － | V9: 1234567_JHA02F02_20150805105600000.csv （氏名コード ＋ _ ＋ ファイルID ＋ _ ＋ 作成時刻 ＋ 拡張子）
C11: 出力対象条件 | AT11: ソート順
C12: csv取込にて取込成功となったレコード | AT12: 特になし
C15: その他
C16: 項目仕様については、外部機能仕様（共通）の出力ファイル項目仕様を参照。
C19: 項目仕様、及び出力イメージについては、外部機能仕様（共通）の出力ファイル項目仕様、及び出力ファイル（補足説明）を参照。

Sheet 出力ファイル項目仕様（エラーリスト）
A1: 出力ファイル項目仕様 | P1: 業 務 | T1: =表紙!AC15 -> 住宅補助費 | AH1: 機 能 | AL1: =表紙!AC23 -> 住宅補助費支給額一括アップロード | AZ1: 作成者 | BC1: =機能概要!BC1 -> 片桐 峻 | BJ1: 作成日 | BM1: =機能概要!BM1 -> 44831
P2: 処 理 | T2: =機能概要!T2 -> 住宅補助費支給額一括アップロード | AH2: 処理種別 | AL2: =機能概要!AL2 -> オンバッチ | AZ2: 修正者 | BJ2: 修正日
C5: 日本語ファイル名 | J5: エラーリスト | AH5: ファイルＩＤ | AM5: JHA02F03
C7: ファイル形式 | L7: レコード形式 | Q7: レコード長 | V7: ファイル名
C9: ＣＳＶ形式 | L9: 可変長 | Q9: － | V9: 1234567_JHA02F03_20150805105600000.csv （氏名コード ＋ _ ＋ ファイルID ＋ _ ＋ 作成時刻 ＋ 拡張子）
C11: 出力対象条件 | AT11: ソート順
C12: csv取込にてチェックエラーとなったレコード | AT12: 特になし
C15: その他
C16: 項目仕様については、外部機能仕様（共通）の出力ファイル項目仕様を参照。
C19: 項目仕様、及び出力イメージについては、外部機能仕様（共通）の出力ファイル項目仕様、及び出力ファイル（補足説明）を参照。

Sheet テーブル更新仕様
A1: テーブル更新仕様 | P1: 業 務 | T1: =表紙!AC15 -> 住宅補助費 | AH1: 機 能 | AL1: =表紙!AC23 -> 住宅補助費支給額一括アップロード | AZ1: 作成者 | BC1: =機能概要!BC1 -> 片桐 峻 | BJ1: 作成日 | BM1: =機能概要!BM1 -> 44831
P2: 処 理 | T2: =機能概要!T2 -> 住宅補助費支給額一括アップロード | AH2: 処理種別 | AL2: =機能概要!AL2 -> オンバッチ | AZ2: 修正者 | BJ2: 修正日
B5: テーブル名 ：住宅補助費申請確定分
B6: 処理パターン：更新
C7: 項番 | F7: 項目名 | T7: 編集仕様
C9: 01 | F9: 手当支給額 | T9: 〔住宅補助費支給額補正ファイル．支給額〕を設定する。
C11: 02 | F11: 適用年月 | T11: 〔住宅補助費支給額補正ファイル．適用年月〕を設定する。
C13: 03 | F13: 給与控除接続フラグ | T13: "0"（未接続）を設定する。
C15: 04 | F15: 最終更新ユーザID | T15: ログイン情報の「氏名コード」を設定する。
C17: 05 | F17: 最終更新日時 | T17: システム日付を設定する。

Sheet 補足説明
A1: 補足説明 | P1: 業 務 | T1: =表紙!AC15 -> 住宅補助費 | AH1: 機 能 | AL1: =表紙!AC23 -> 住宅補助費支給額一括アップロード | AZ1: 作成者 | BC1: =機能概要!BC1 -> 片桐 峻 | BJ1: 作成日 | BM1: =機能概要!BM1 -> 44831
P2: 処 理 | T2: =機能概要!T2 -> 住宅補助費支給額一括アップロード | AH2: 処理種別 | AL2: =機能概要!AL2 -> オンバッチ | AZ2: 修正者 | BJ2: 修正日
B5: １．住宅補助費支給額補正ファイルのイメージ
C7: 氏名コード,借家番号,申請ID,支給額,適用年月 | AX7: ← ヘッダ部
C8: 1234567,X,XXXXXXXXXXXXXXXX,123456,YYYYMM | AX8: ← データ部
C9: 1234567,X,XXXXXXXXXXXXXXXX,123456,YYYYMM
B13: 2．処理結果リストファイルのイメージ
C15: 氏名コード,借家番号,申請ID,支給額,適用年月 | AX15: ← ヘッダ部
C16: 1234567,X,XXXXXXXXXXXXXXXX,123456,YYYYMM,更新結果：メッセージ | AX16: ← データ部
B22: ３．エラーリストファイルのイメージ
C24: 氏名コード,借家番号,申請ID,支給額,適用年月 | AX24: ← ヘッダ部
C25: 1234567,X,XXXXXXXXXXXXXXXX,123456,YYYYMM,エラーメッセージ | AX25: ← データ部
