Workbook

Sheet 表紙
C2: 厚生系統合システム
C6: 外部機能仕様（機能別）
Q11: 構成管理番号 | AC11: KSED-GYB10
Q15: 業務名 | AC15: 業務共通
Q19: 機能ＩＤ | AC19: GYB10
Q23: 機能名 | AC23: 給与控除結果テーブル作成

Sheet 変更内容一覧
C2: 厚生系統合システム | AI2: 外部機能仕様（機能別）
AD6: 変更内容一覧
C9: 機能ＩＤ | H9: GYB10 | V9: 機能名 | AA9: 給与控除結果テーブル作成
C12: 管理番号 | L12: 版 | P12: 変更理由 | AH12: 変更内容 | AZ12: 変更箇所 | BJ12: 変更区分 | BO12: 作成者 ・日付
L14: 1.0 | P14: 新規 | BJ14: 更新 | BO14: 2015/12/28 多羅尾
BJ15: 追加
BJ16: 削除
C17: 仕変設変No-00001 | L17: 1.0 | P17: テーブル定義横並び修正に伴う修正 | AH17: 社員氏名コード⇒氏名コードに更新 | AZ17: ・テーブル更新仕様 | BJ17: 更新 | BO17: 2016/3/9 志水
BJ18: 追加
BJ19: 削除
C20: 仕変設変No-00009 | L20: 1.0 | P20: メッセージの統一 | AH20: 共通メッセージIDの反映 | AZ20: チェック仕様 | BJ20: 更新 | BO20: 2015/03/15 山口
BJ21: 追加
BJ22: 削除
C23: 仕変設変No-00008 | L23: 1.0 | P23: ED書の誤字／脱字／記述改善の反映を行う | AH23: 誤記の修正・脱字の追記・記述不明確箇所の改善・文末形式の統一 | AZ23: Mantis添付資料に詳細内容があるため、省略 | BJ23: 更新 | BO23: 矢野 2016/3/23
BJ24: 追加
BJ25: 削除
C26: 仕変設変No-00058 | L26: 1.0 | P26: コード仕様の設計変更 | AH26: 在職区分コードの和名を下記の通り修正。 「在Ａ出向」→「現在員(在A,C等出向)」 | AZ26: 補足説明 | BJ26: 更新 | BO26: 2016/4/20 矢野
BJ27: 追加
BJ28: 削除
C29: 仕変設変No-00188 | L29: 1.0 | P29: M/UT工程実施に伴う外部設計書への反映 | AH29: [給与控除．給与計算システムコード］が"09"（全給与システム控除依頼）⇒[給与控除．給与計算システムコード］が"06"（全給与システム控除依頼）に修正。 | AZ29: 補足説明 | BJ29: 更新 | BO29: 2016/8/22 松賀
BJ30: 追加
BJ31: 削除
C32: 仕変設変No-00210 | L32: 1.0 | P32: 組織コード、部課コード、ビルコード、役職コードの属性変更 | AH32: 組織コードのバリデーションチェックを半角数字から半角英数を許容するよう修正。 | AZ32: 出力ファイル項目仕様 | BJ32: 更新 | BO32: 2016/8/30 松賀
BJ33: 追加
BJ34: 削除
C35: 仕変設変No-00328 | L35: 1.1 | P35: 給与控除結果テーブル作成のロジック修正 | AH35: ■修正前 組織マスタより組織コードを基に会社コードを取得 ■修正後 社員１日情報より氏名コード、控除年月、給与支給組織コードを基に給与支給会社コードを取得 | AZ35: 機能概要 機能詳細 テーブル更新仕様 | BJ35: 更新 | BO35: 2017/1/4 松賀
BJ36: 追加
BJ41: 削除
C42: 仕変設変No-00417 | L42: 1.1 | P42: 財形控除結果ファイルチェックリストの設計修正 | AH42: ・財形控除結果ファイルチェックリストのファイル名に拡張子「.csv」を追記 ・財形控除結果ファイルチェックリストの下記項目名を修正 （誤） 社内社員氏名カナ （正） 社員社内氏名カナ | AZ42: 出力ファイル項目仕様 | BJ42: 更新 | BO42: 2017/2/7 松賀
BJ43: 追加
BJ44: 削除
C45: 仕変設変No-00502 | L45: 1.1 | P45: 給与控除結果テーブル作成における会社コードの設定ロジック変更 | AH45: Mantis添付資料に詳細内容があるため省略 | AZ45: チェック仕様 出力ファイル項目仕様 | BJ45: 更新 | BO45: 2017/3/10 松賀
BJ46: 追加
BJ47: 削除
C51: 商用仕変設変No-00060 | L51: 1.2 | P51: 給与控除テーブルの「控除結果会社」が未設定の社員について、「財形控除結果ファイルチェックリスト」に出力されていない。 | AH51: 財形控除結果ファイルチェックリストの出力条件を修正する。 | AZ51: 出力ファイル項目仕様 補足説明 | BJ51: 更新 | BO51: 2017/8/18 松賀
BJ52: 追加
BJ53: 削除

Sheet 機能概要
A1: 機能概要 | P1: 業 務 | T1: 業務共通 | AH1: 機 能 | AL1: 給与控除結果テーブル作成 | AZ1: 作成者 | BC1: 多羅尾 | BJ1: 作成日 | BM1: 42366
P2: 処 理 | T2: 控除情報管理 | AH2: 処理種別 | AL2: バッチ | AZ2: 修正者 | BJ2: 修正日
B5: 機能概要 | AM5: データフロー
B6: 前処理で作成された〔チェック済み給与控除結果ファイル〕を全てマージし、重複レコードチェック後に[給与控除結果]を作成する。 当処理でエラーとなった場合、[財形控除結果ファイルチェックリスト]を出力する。
B22: 前提条件・制約事項・運用上の留意事項
B23: １．バッチ起動条件 【起動条件】 ：ジョブスケジューラによる起動 【処理周期】 ：月次、または手当発生時 【起動パラメータ】：起動識別（1：例月 2：夏ボーナス 3：冬ボーナス） 【関連機能】 【前処理】 ：給与控除結果取込チェック 【後処理】 ：給与控除結果取込（財形） ２．その他（制約事項、運用上の留意事項） なし
B37: セキュリティ要件
B38: なし

Sheet 機能詳細
A1: 機能詳細 | P1: 業 務 | T1: =機能概要!T1 -> 業務共通 | AH1: 機 能 | AL1: =機能概要!AL1 -> 給与控除結果テーブル作成 | AZ1: 作成者 | BC1: 多羅尾 | BJ1: 作成日 | BM1: =機能概要!BM1 -> 42366
P2: 処 理 | T2: =機能概要!T2 -> 控除情報管理 | AH2: 処理種別 | AL2: =機能概要!AL2 -> バッチ | AZ2: 修正者 | BJ2: 修正日
A4: 入力 | N4: 処理 | BC4: イベントID | BH4: 出力
O6: １．開始処理
O7: （１）開始メッセージをログに出力する。（「チェック仕様」01参照）
O8: （２）パラメータ情報を取得する。
P9: パラメータ数が不正の場合、ログにエラーメッセージを出力し、処理を異常終了する。（「チェック仕様」03参照）
O11: （３）入出力ファイルをオープンする。
D12: ・ＳＰＥＡＤ | P12: オープンに失敗した場合、ログにエラーメッセージを出力し、処理を異常終了する。（「チェック仕様」04参照）
D13: ・ＩＮＦＯＧＲＩＤ | P13: ・〔チェック済み給与控除結果ファイル〕
D14: ・ＣＯＭＳ | P14: ・〔マージ済み給与控除結果ファイル〕
P15: ・〔財形控除結果ファイルチェックリスト〕
O17: （４）ＤＢのトランザクションを開始する。
O18: （５）〔チェック済み給与控除結果ファイル〕を全てマージし、〔マージ済み給与控除結果ファイル〕を作成する。
Q19: 〔マージ済み給与控除結果ファイル〕は氏名コードで昇順にソートする。
Q20: （「チェック仕様」05,06参照）
O22: （６）〔財形控除結果ファイルチェックリスト〕を作成する。
P23: ※〔財形控除結果ファイルチェックリスト〕のヘッダーレコードとファイル見出しを作成する。（「出力ファイル仕様」参照）
P24: 書き込みに失敗した場合はエラーメッセージをログに出力し、処理を終了する。（「チェック仕様」05参照）
O26: ２．主処理
O27: （１）処理実行判定
P28: ア．先頭レコードを参照する。
P29: （ア）〔マージ済み給与控除結果ファイル．レコード・シーケンスＮＯ〕が“0000000”（先頭レコード）に一致するものを取得する。
Q30: ａ．１件目の先頭レコードより、以下の項目を取得し、チェックする。
R31: ・〔マージ済み給与控除結果ファイル．例月賞与区分〕（「チェック仕様」08,09参照）
Q33: ｂ．[業務日付]、[処理実行判定ワーク]から必要項目を取得し、チェックする。
E34: 処理実行判定ワーク | R34: ・チェック内容は下記を参照
E35: 業務日付 | S35: （「チェック仕様」10,11,12,13,14,15参照）
O37: （２）初期化処理
P38: ア．[給与控除結果]のレコードを全て削除する。
O40: （３）[給与控除結果]登録処理
P41: 〔マージ済み給与控除結果ファイル．レコード・シーケンスＮＯ〕が“9999999”
P42: または〔マージ済み給与控除結果ファイル〕のレコードが終了するまで下記処理を繰り返す。
P43: 読み込みに失敗した場合はエラーメッセージをログに出力し、処理を終了する。（「チェック仕様」06参照）
P45: ア．〔マージ済み給与控除結果ファイル．レコード・シーケンスＮＯ〕が“0000000”（先頭レコード）の場合、
Q46: 次レコードを読み込む。
P48: イ．〔マージ済み給与控除結果ファイル．氏名コード〕をワーク変数に格納する。
P49: ウ．〔マージ済み給与控除結果ファイル．氏名コード〕がワーク変数の氏名コードと一致する場合、次レコードを読み込む。
Q50: 異なる場合は「エ」へ遷移する。
P53: エ．氏名コードが重複している場合、
...

Sheet チェック仕様
A1: チェック仕様 | P1: 業 務 | T1: =機能概要!T1 -> 業務共通 | AH1: 機 能 | AL1: =機能概要!AL1 -> 給与控除結果テーブル作成 | AZ1: 作成者 | BC1: 多羅尾 | BJ1: 作成日 | BM1: =機能概要!BM1 -> 42366
P2: 処 理 | T2: =機能概要!T2 -> 控除情報管理 | AH2: 処理種別 | AL2: =機能概要!AL2 -> バッチ | AZ2: 修正者 | BJ2: 修正日
B6: 項番 | D6: チェック項目 | J6: チェック内容 | X6: チェック契機 | AD6: 出力先 | AH6: 重要度 | AL6: メッセージID | AQ6: メッセージテキスト | BH6: 埋込情報 | BR6: 英語 対応
B8: 01 | D8: 開始ログ | J8: － | X8: 処理開始時 | AD8: ＡＰログ | AH8: 確認 | AL8: SSB00I001 | AQ8: %1 処理開始 | BH8: %1："給与控除結果テーブル作成"
B10: 02 | D10: 終了ログ | J10: － | X10: 処理終了時 | AD10: ＡＰログ | AH10: 確認 | AL10: SSB00I002 | AQ10: %1 処理終了 | BH10: %1："給与控除結果テーブル作成"
B12: 03 | D12: 起動パラメータ | J12: パラメータ数が正しく設定されていること。 | X12: パラメータ取得時 | AD12: ＡＰログ | AH12: 異常 | AL12: GYB10F001 | AQ12: 起動パラメータ数が不正です。
B14: 04 | D14: ファイルオープン | J14: ファイルがオープンできること。 | X14: ファイルオープン時 | AD14: ＡＰログ | AH14: エラー | AL14: SSB00E003 | AQ14: ファイルオープン時にエラーが発生しました。[ファイル:%1] | BH14: %1：ファイル物理名
B16: 05 | D16: ファイル出力 | J16: ファイルが書き込みできること。 | X16: ファイル書込時 | AD16: ＡＰログ | AH16: エラー | AL16: SSB00E008 | AQ16: ファイル出力時にエラーが発生しました。[ファイル:%1] | BH16: %1：ファイル物理名
B18: 06 | D18: ファイル読込 | J18: ファイルが読み込みできること。 | X18: ファイル読込時 | AD18: ＡＰログ | AH18: エラー | AL18: SSB00E016 | AQ18: ファイル読込時にエラーが発生しました。[ファイル:%1] | BH18: %1：ファイル物理名
B20: 07 | D20: ファイルクローズ | J20: ファイルがクローズできること。 | X20: ファイルクローズ時 | AD20: ＡＰログ | AH20: エラー | AL20: SSB00E004 | AQ20: ファイルクローズ時にエラーが発生しました。[ファイル:%1] | BH20: %1：ファイル物理名
B22: 08 | D22: 例月賞与区分 | J22: 起動パラメータの起動識別が“1”の場合、 〔マージ済み給与控除結果ファイル例月・賞与区分〕が“1”であること 。 | X22: 処理実行判定 | AD22: ＡＰログ | AH22: 異常 | AL22: GYB10F006 | AQ22: 例月賞与区分が起動識別と一致しません。[起動識別：%1] | BH22: %1:起動パラメータの起動識別
B24: 09 | D24: 例月賞与区分 | J24: 起動パラメータの起動識別が“2”または“3”の場合、 〔マージ済み給与控除結果ファイル．例月賞与区分〕が“2”であること。 | X24: 処理実行判定 | AD24: ＡＰログ | AH24: 異常 | AL24: GYB10F006 | AQ24: 例月賞与区分が起動識別と一致しません。[起動識別：%1] | BH24: %1:起動パラメータの起動識別
B26: 10 | D26: 給与支給年月日の年月 | J26: 起動パラメータの起動識別が"1"のとき「処理実行判定ワーク」. 「毎月給与支給年月日」の 年月と同一であること。 | X26: 処理実行判定 | AD26: ＡＰログ | AH26: 異常 | AL26: GYB10F007 | AQ26: 給与支給年月日の年月が処理実行判定ワークテーブルと一致しません。[%1] | BH26: %1：（例月）
B28: 11 | D28: 給与支給年月日の年月 | J28: 起動パラメータの起動識別が"2"のとき[処理実行判定ワーク.夏ﾎﾞｰﾅｽ給与支給年月日]の 年月と同一であること。 | X28: 処理実行判定 | AD28: ＡＰログ | AH28: 異常 | AL28: GYB10F007 | AQ28: 給与支給年月日の年月が処理実行判定ワークテーブルと一致しません。[%1] | BH28: %1：（ボーナス（夏））
B30: 12 | D30: 給与支給年月日の年月 | J30: 起動パラメータの起動識別が"3"のとき[処理実行判定ワーク.冬ﾎﾞｰﾅｽ給与支給年月日]の 年月と同一であること。 | X30: 処理実行判定 | AD30: ＡＰログ | AH30: 異常 | AL30: GYB10F007 | AQ30: 給与支給年月日の年月が処理実行判定ワークテーブルと一致しません。[%1] | BH30: %1：（ボーナス（冬））
B32: 13 | D32: 業務日付 | J32: 起動パラメータの起動識別が"1"のとき[処理実行判定ワーク.毎月給与控除結果登録年月日]の 年月が[業務日付．業務日付]の年月と等しくないこと。 | X32: 処理実行判定 | AD32: ＡＰログ | AH32: 異常 | AL32: GYB10F008 | AQ32: 給与控除結果登録処理が実行されています。
B34: 14 | D34: 業務日付 | J34: 起動パラメータの起動識別が"2"のとき[処理実行判定ワーク.夏ﾎﾞｰﾅｽ給与控除結果登録年月日]の年月が[業務日付．業務日付]の年月と等しくないこと。 | X34: 処理実行判定 | AD34: ＡＰログ | AH34: 異常 | AL34: GYB10F008 | AQ34: 給与控除結果登録処理が実行されています。
B36: 15 | D36: 業務日付 | J36: 起動パラメータの起動識別が"3"のとき[処理実行判定ワーク.冬ﾎﾞｰﾅｽ給与控除結果登録年月日]の年月が[業務日付．業務日付]の年月と等しくないこと。 | X36: 処理実行判定 | AD36: ＡＰログ | AH36: 異常 | AL36: GYB10F008 | AQ36: 給与控除結果登録処理が実行されています。
B38: 16 | D38: 会社コード | J38: [社員１日情報]より[社員１日情報．給与支給会社コード]が取得できること。 | X38: 主処理時 | AD38: 財形控除結果ファイルチェックリスト | AH38: エラー | AL38: GYB10E001 | AQ38: 控除結果会社が特定できません。給与控除結果補正画面から設定願います。

Sheet 入力ファイル項目仕様
A1: 入力ファイル項目仕様 | P1: 業 務 | T1: =機能概要!T1 -> 業務共通 | AH1: 機 能 | AL1: =機能概要!AL1 -> 給与控除結果テーブル作成 | AZ1: 作成者 | BC1: 多羅尾 | BJ1: 作成日 | BM1: =機能概要!BM1 -> 42366
P2: 処 理 | T2: =機能概要!T2 -> 控除情報管理 | AH2: 処理種別 | AL2: =機能概要!AL2 -> バッチ | AZ2: 修正者 | BJ2: 修正日
C5: 日本語ファイル名 | J5: チェック済み給与控除結果ファイル | AH5: ファイルＩＤ
C7: ファイル形式 | L7: レコード形式 | Q7: レコード長 | V7: ファイル名
C9: ＳＡＭ | L9: 固定長 | Q9: 101 | V9: “CHECK_FIN_”＋起動パラメータのファイル名 ※ジョブ単位に指定
C11: 入力ファイル説明
C12: 各人事給与システムより連携した給与控除結果ファイル。
C15: その他
C16: －
C19: ・先頭レコード
C20: 項番 | F20: 項目名 | T20: 属性 | W20: 桁数 | AA20: 共通チェックID | AF20: 必須 | AH20: 項目説明
W21: 最小 | Y21: 最大
C22: 01 | F22: レコードシーケンスＮＯ | T22: 9 | W22: － | Y22: 7 | AA22: － | AF22: ○ | AH22: レコードシーケンスＮＯを設定する。
C24: 02 | F24: ソート用ダミー | T24: 9 | W24: － | Y24: 7 | AA24: － | AF24: － | AH24: ソート用ダミーを設定する。
C26: 03 | F26: 給与支給年月日 | T26: 9 | W26: － | Y26: 8 | AA26: － | AF26: ○ | AH26: 給与支給年月日を設定する。
C28: 04 | F28: 例月・賞与区分 | T28: 9 | W28: － | Y28: 1 | AA28: － | AF28: ○ | AH28: 例月・賞与区分を設定する。
C30: 05 | F30: 予備 | T30: X | W30: － | Y30: 77 | AA30: － | AF30: － | AH30: 予備を設定する。
C32: 06 | F32: 改行コード | T32: X | W32: － | Y32: 1 | AA32: － | AF32: ○ | AH32: 改行コード（ＣＲＬＦ）を設定する。
C52: ・データレコード
C53: 項番 | F53: 項目名 | T53: 属性 | W53: 桁数 | AA53: 共通チェックID | AF53: 必須 | AH53: 項目説明
W54: 最小 | Y54: 最大
C55: 01 | F55: レコードシーケンスＮＯ | T55: 9 | W55: － | Y55: 7 | AA55: － | AF55: ○ | AH55: レコードシーケンスＮＯを設定する。
C57: 02 | F57: 氏名コード | T57: 9 | W57: － | Y57: 7 | AA57: － | AF57: ○ | AH57: 氏名コードを設定する。
C59: 03 | F59: 管一区分コード | T59: X | W59: － | Y59: 1 | AA59: － | AF59: － | AH59: 管一区分コードを設定する。
C61: 04 | F61: 組織コード | T61: X | W61: － | Y61: 8 | AA61: － | AF61: － | AH61: 組織コードを設定する。
C63: 05 | F63: 部課コード | T63: X | W63: － | Y63: 7 | AA63: － | AF63: － | AH63: 部課コードを設定する。
C65: 06 | F65: カナ氏名 | T65: X | W65: － | Y65: 20 | AA65: － | AF65: － | AH65: カナ氏名を設定する。
C67: 07 | F67: 正常・エラーＦＬＧ | T67: 9 | W67: － | Y67: 1 | AA67: － | AF67: － | AH67: 正常・エラーＦＬＧを設定する。
C69: 08 | F69: 財形フラグ | T69: 9 | W69: － | Y69: 2 | AA69: － | AF69: ○ | AH69: 財形フラグを設定する。
C71: 09 | F71: 財形貯蓄控除額 | T71: X | W71: － | Y71: 7 | AA71: － | AF71: － | AH71: 財形貯蓄控除額を設定する。
C73: 10 | F73: 異動コード | T73: X | W73: － | Y73: 3 | AA73: － | AF73: － | AH73: 異動コードを設定する。
C75: 11 | F75: 社員識別 | T75: X | W75: － | Y75: 1 | AA75: － | AF75: － | AH75: 社員識別を設定する。
C77: 12 | F77: 在職区分 | T77: X | W77: － | Y77: 2 | AA77: － | AF77: － | AH77: 在職区分を設定する。
C79: 13 | F79: 給与支給区分 | T79: X | W79: － | Y79: 1 | AA79: － | AF79: － | AH79: 給与支給区分を設定する。
C81: 14 | F81: 出向種別コード | T81: X | W81: － | Y81: 1 | AA81: － | AF81: － | AH81: 出向種別コードを設定する。
C83: 15 | F83: 予備 | T83: X | W83: － | Y83: 32 | AA83: － | AF83: － | AH83: 予備を設定する。
C85: 16 | F85: 改行コード | T85: X | W85: － | Y85: 1 | AA85: － | AF85: ○ | AH85: 改行コード（ＣＲＬＦ）を設定する。
C100: ・管理レコード
C101: 項番 | F101: 項目名 | T101: 属性 | W101: 桁数 | AA101: 共通チェックID | AF101: 必須 | AH101: 項目説明
W102: 最小 | Y102: 最大
...

Sheet 出力ファイル項目仕様
A1: 出力ファイル項目仕様 | P1: 業 務 | T1: =機能概要!T1 -> 業務共通 | AH1: 機 能 | AL1: =機能概要!AL1 -> 給与控除結果テーブル作成 | AZ1: 作成者 | BC1: 多羅尾 | BJ1: 作成日 | BM1: =機能概要!BM1 -> 42366
P2: 処 理 | T2: =機能概要!T2 -> 控除情報管理 | AH2: 処理種別 | AL2: =機能概要!AL2 -> バッチ | AZ2: 修正者 | BJ2: 修正日
C5: 日本語ファイル名 | J5: マージ済み給与控除結果ファイル | AH5: ファイルＩＤ | AM5: GYB10F02
C7: ファイル形式 | L7: レコード形式 | Q7: レコード長 | V7: ファイル名
C9: ＳＡＭ | L9: 固定長 | Q9: 101 | V9: GYB10F02_TEMP_01_yyyyMMddHHmmssSSS
C11: 出力対象条件 | AT11: ソート順
C12: － | AT12: 氏名コードで昇順
C15: その他
C16: 各人給の〔チェック済み給与控除結果ファイル〕をマージしたファイル。
C20: ・先頭レコード
C21: 項番 | F21: 項目名 | T21: 編集 | Z21: 項目説明
T22: 属性 | W22: 桁数
C23: 01 | F23: レコードシーケンスＮＯ | T23: 9 | W23: 7 | Z23: 〔チェック済み給与控除結果ファイル.レコードシーケンスＮＯ〕を設定する。
C25: 02 | F25: ソート用ダミー | T25: 9 | W25: 7 | Z25: 〔チェック済み給与控除結果ファイル.ソート用ダミー〕を設定する。
C27: 03 | F27: 給与支給年月日 | T27: 9 | W27: 8 | Z27: 〔チェック済み給与控除結果ファイル.給与支給年月日〕を設定する。
C29: 04 | F29: 例月・賞与区分 | T29: 9 | W29: 1 | Z29: 〔チェック済み給与控除結果ファイル.例月・賞与区分〕を設定する。
C31: 05 | F31: 予備 | T31: X | W31: 77 | Z31: 〔チェック済み給与控除結果ファイル.予備〕を設定する。
C33: 06 | F33: 改行コード | T33: X | W33: 1 | Z33: 改行コード（ＣＲＬＦ）を設定する。
C50: ・データレコード
C51: 項番 | F51: 項目名 | T51: 編集 | Z51: 項目説明
T52: 属性 | W52: 桁数
C53: 01 | F53: レコードシーケンスＮＯ | T53: 9 | W53: 7 | Z53: 〔チェック済み給与控除結果ファイル.レコードシーケンスＮＯ〕を設定する。
C55: 02 | F55: 氏名コード | T55: 9 | W55: 7 | Z55: 〔チェック済み給与控除結果ファイル.氏名コード〕を設定する。
C57: 03 | F57: 管一区分コード | T57: X | W57: 1 | Z57: 〔チェック済み給与控除結果ファイル.管一区分コード〕を設定する。
C59: 04 | F59: 組織コード | T59: X | W59: 8 | Z59: 〔チェック済み給与控除結果ファイル.組織コード〕を設定する。
C61: 05 | F61: 部課コード | T61: X | W61: 7 | Z61: 〔チェック済み給与控除結果ファイル.部課コード〕を設定する。
C63: 06 | F63: カナ氏名 | T63: X | W63: 20 | Z63: 〔チェック済み給与控除結果ファイル.カナ氏名〕を設定する。
C65: 07 | F65: 正常・エラーＦＬＧ | T65: 9 | W65: 1 | Z65: 〔チェック済み給与控除結果ファイル.正常・エラーＦＬＧ〕を設定する。
C67: 08 | F67: 財形フラグ | T67: 9 | W67: 2 | Z67: 〔チェック済み給与控除結果ファイル.財形フラグ〕を設定する。
C69: 09 | F69: 財形貯蓄控除額 | T69: X | W69: 7 | Z69: 〔チェック済み給与控除結果ファイル.財形貯蓄控除額〕を設定する。
C71: 10 | F71: 異動コード | T71: X | W71: 3 | Z71: 〔チェック済み給与控除結果ファイル.異動コード〕を設定する。
C73: 11 | F73: 社員識別 | T73: X | W73: 1 | Z73: 〔チェック済み給与控除結果ファイル．社員識別〕を設定する。
C75: 12 | F75: 在職区分 | T75: X | W75: 2 | Z75: 〔チェック済み給与控除結果ファイル．在職区分〕を設定する。
C77: 13 | F77: 給与支給区分 | T77: X | W77: 1 | Z77: 〔チェック済み給与控除結果ファイル．給与支給区分〕を設定する。
C79: 14 | F79: 出向種別コード | T79: X | W79: 1 | Z79: 〔チェック済み給与控除結果ファイル．出向種別コード〕を設定する。
C81: 15 | F81: 予備 | T81: X | W81: 32 | Z81: 〔チェック済み給与控除結果ファイル．予備〕を設定する。
C83: 16 | F83: 改行コード | T83: X | W83: 1 | Z83: 改行コード（ＣＲＬＦ）を設定する。
C98: ・管理レコード
C99: 項番 | F99: 項目名 | T99: 編集 | Z99: 項目説明
T100: 属性 | W100: 桁数
...

Sheet テーブル更新仕様
A1: テーブル更新仕様 | P1: 業 務 | T1: =機能概要!T1 -> 業務共通 | AH1: 機 能 | AL1: =機能概要!AL1 -> 給与控除結果テーブル作成 | AZ1: 作成者 | BC1: 多羅尾 | BJ1: 作成日 | BM1: =機能概要!BM1 -> 42366
P2: 処 理 | T2: =機能概要!T2 -> 控除情報管理 | AH2: 処理種別 | AL2: =機能概要!AL2 -> バッチ | AZ2: 修正者 | BC2: 志水 | BJ2: 修正日 | BM2: 42438
B5: テーブル名 ：給与控除結果
B6: 処理パターン：追加
C8: 項番 | F8: 項目名 | T8: 編集仕様
C10: 01 | F10: 氏名コード | T10: 〔マージ済み給与控除結果ファイル．氏名コード〕を設定する。
C12: 02 | F12: 給与支給年月日 | T12: 〔マージ済み給与控除結果ファイル．給与支給年月日〕を設定する。
C14: 03 | F14: 積立区分コード | T14: 起動パラメータの「起動識別」を設定する。
C16: 04 | F16: 管一区分コード | T16: 〔マージ済み給与控除結果ファイル．管一コード〕を設定する。
C18: 05 | F18: 組織コード | T18: 〔マージ済み給与控除結果ファイル．組織コード〕を設定する。
C20: 06 | F20: 部課コード | T20: 〔マージ済み給与控除結果ファイル．部課コード〕を設定する。
C22: 07 | F22: 社員社内氏名カナ | T22: 〔マージ済み給与控除結果ファイル．カナ氏名〕を設定する。
C24: 08 | F24: 正常エラーフラグ | T24: 〔マージ済み給与控除結果ファイル．正常・エラーＦＬＧ〕を設定する。
C26: 09 | F26: 財形フラグ | T26: 〔マージ済み給与控除結果ファイル．財形フラグ〕を設定する。
C28: 10 | F28: 財形貯蓄控除金額 | T28: 〔マージ済み給与控除結果ファイル．財形貯蓄控除額〕が数字の場合は〔マージ済み給与控除結果．財形貯蓄控除額〕を設定する。 〔マージ済み給与控除結果ファイル．財形貯蓄控除額〕が数字以外の場合は“0”を設定する。
C30: 11 | F30: 異動コード | T30: 〔マージ済み給与控除結果ファイル．異動コード〕を設定する。
... C46: 19 | F46: 最終更新ユーザＩＤ | T46: 機能ＩＤを設定する。

Sheet 補足説明
A1: 補足説明 | P1: 業 務 | T1: =機能概要!T1 -> 業務共通 | AH1: 機 能 | AL1: =機能概要!AL1 -> 給与控除結果テーブル作成 | AZ1: 作成者 | BC1: 多羅尾 | BJ1: 作成日 | BM1: =機能概要!BM1 -> 42366
P2: 処 理 | T2: =機能概要!T2 -> 控除情報管理 | AH2: 処理種別 | AL2: =機能概要!AL2 -> バッチ | AZ2: 修正者 | BJ2: 修正日
C6: １．重複チェック仕様
C7: （１）重複件数が２件の場合
D8: ア．下記のパターンに該当する場合、２件重複パターン表のチェック条件「有効・無効」を「無効」とする。
D9: （ア）〔マージ済み給与控除結果ファイル．異動コード〕が"300"（退職）のレコード
D10: （イ）〔マージ済み給与控除結果ファイル．在職区分コード〕が"10"（現在員(在A,C等出向)）かつ〔マージ済み給与控除結果ファイル．給与支給区分〕が"9"（無給）のレコード
D11: 上記以外のレコードは「有効」とする。
D14: ２件重複パターン表
D15: パターン 番号 | G15: チェック条件 | S15: 財形控除結果ファイル チェックリスト | AE15: 給与 控除結果 テーブル作成 | AH15: 備 考
G16: マージ済み給与控除結果ファイル※４ | S16: 出力有無 | V16: 重複エラー表示 | Y16: 登録表示 | AB16: 会社コード取得エラー
G17: 有効・無効 | M17: 財形フラグ
D18: 1 | G18: 無効※１ | M18: 00(控除依頼なし) | S18: ○ | V18: ○ | Y18: × | AB18: × | AE18: ×
G19: 無効※１ | M19: 00(控除依頼なし) | S19: ○ | V19: ○ | Y19: × | AB19: × | AE19: ×
D20: 2 | G20: 無効※１ | M20: 00(控除依頼なし) | S20: ○ | V20: ○ | Y20: × | AB20: × | AE20: ×
G21: 無効※１ | M21: 00以外※２ | S21: ○ | V21: ○ | Y21: ○ | AB21: ○ | AE21: ○
D22: 3 | G22: 無効※１ | M22: 00以外※２ | S22: ○ | V22: ○ | Y22: × | AB22: × | AE22: ×
G23: 無効※１ | M23: 00以外※２ | S23: ○ | V23: ○ | Y23: × | AB23: × | AE23: ×
D24: 4 | G24: 無効※１ | M24: 00(控除依頼なし) | S24: × | V24: － | Y24: － | AB24: × | AE24: × | AH24: 東西会社（ＳＰＥＡＤ）から共同利用外に在Ａ出向しているパターンまたは退職再雇用、転籍のパターン
G25: 有効 | M25: － | S25: ○ | V25: － | Y25: － | AB25: ○ | AE25: ○
D26: 5 | G26: 無効※１ | M26: 00以外※２ | S26: ○ | V26: ○ | Y26: ○ | AB26: ○ | AE26: ○ | AH26: 上記と同様だが、財形控除依頼が出向元に対して行われたパターン
G27: 有効 | M27: 00(控除依頼なし) | S27: ○ | V27: ○ | Y27: × | AB27: × | AE27: ×
D28: 6 | G28: 無効※１ | M28: 00以外※２ | S28: ○ | V28: ○ | Y28: × | AB28: × | AE28: × | AH28: ２給与システムに控除依頼をしたパターン （通常ありえない）
G29: 有効 | M29: 00以外※２ | S29: ○ | V29: ○ | Y29: × | AB29: × | AE29: ×
D30: 7 | G30: 有効 | M30: 00(控除依頼なし) | S30: ○ | V30: ○ | Y30: × | AB30: × | AE30: ×
G31: 有効 | M31: 00(控除依頼なし) | S31: ○ | V31: ○ | Y31: × | AB31: × | AE31: ×
D32: 8 | G32: 有効 | M32: 00(控除依頼なし) | S32: ○ | V32: ○ | Y32: × | AB32: × | AE32: ×
G33: 有効 | M33: 00以外※２ | S33: ○ | V33: ○ | Y33: ○ | AB33: ○ | AE33: ○
D34: 9 | G34: 有効 | M34: 00以外※２ | S34: ○ | V34: ○ | Y34: × | AB34: × | AE34: ×
G35: 有効 | M35: 00以外※２ | S35: ○ | V35: ○ | Y35: × | AB35: × | AE35: ×
D36: パターン表の財形控除結果ファイルチェックリストの項目に○がついているものは〔財形控除結果ファイルチェックリスト〕を作成する。（「出力ファイル項目仕様」参照）
D37: パターン表の給与控除結果テーブル作成の項目に○がついているものは[給与控除結果]を更新する。（「テーブル更新仕様」参照）
C54: （２）重複件数が３件以上の場合
D55: 〔マージ済み給与控除結果ファイル．氏名コード〕、マージ済み給与控除結果ファイル．積立区分コード〕をキーとして[給与控除]を参照し、[給与控除．給与計算システムコード]を取得する。
D56: ア．[給与控除．給与計算システムコード］が"06"（全給与システム控除依頼）以外またはレコードが存在しない場合
E57: 下記パターン表を元に処理の判定を行う。
F59: ３件以上重複パターン表①（ア．に該当する場合）
F60: パターン 番号 | I60: チェック条件 | U60: 財形控除結果ファイルチェックリスト | AG60: 給与 控除結果 テーブル作成 | AJ60: 備 考
I61: マージ済み給与控除結果ファイル※４ | U61: 出力有無 | X61: 重複エラー表示 | AA61: 登録表示 | AD61: 会社コード取得エラー
I62: 財形フラグ | O62: レコード数
...
