Workbook
Name e: [1]Sheet2!$A$1:$B$986
Name enm: [2]Sheet2!$A$1:$B$986
Name 種別: #REF!
Name 種別: #REF!
Name 種別: #REF!

Sheet 表紙
C2: 厚生系統合システム
C6: 外部機能仕様（機能別）
Q11: 構成管理番号 | AC11: KSED-CHA10
Q15: 業務名 | AC15: 社宅
Q19: 機能ＩＤ | AC19: CHA10
Q23: 機能名 | AC23: 入居申請（人事）

Sheet 変更内容一覧
C2: 厚生系統合システム | AI2: 外部機能仕様（機能別）
AD6: 変更内容一覧
C9: 機能ＩＤ | H9: =表紙!AC19 -> CHA10 | V9: 機能名 | AA9: =表紙!AC23 -> 入居申請（人事）
C12: 管理番号 | L12: 版 | P12: 変更理由 | AH12: 変更内容 | AZ12: 変更箇所 | BJ12: 変更区分 | BO12: 作成者 ・日付
L14: 1.0 | P14: 新規作成 | AH14: － | AZ14: － | BJ14: 更新 | BO14: 白取 2015/12/28
BJ15: 追加
BJ16: 削除
C17: 仕変設変No-00001 | L17: 1.0 | P17: テーブル定義横並び修正 | AH17: 名称の統一、ＩＤの統一及び型桁の統一 | AZ17: Mantis添付資料に詳細内容があるため、省略 | BJ17: 更新 | BO17: 井上 2016/2/29
BJ18: 追加
BJ19: 削除
C20: 仕変設変No-00007 | L20: 1.0 | P20: 年齢チェックの誤り対応 | AH20: 年齢チェックを削除する。 | AZ20: 機能詳細 項番１（１）イ 機能詳細 項番１（６） チェック仕様 | BJ20: 更新 | BO20: 井上 2016/3/8
BJ21: 追加
BJ22: 削除
C23: 仕変設変No-00008 | L23: 1.0 | P23: 誤字・脱字・機能改善・文末形式の統一修正 | AH23: ①スタッフ用の検索画面における英語対応を除外する。 ②カフェポイント申請チェックを行う条件を記載する。 ③メールアドレスを取得先の誤り | AZ23: ①チェック仕様：２．項番01～06 ②機能詳細：項番１（１）ア ③画面項目仕様：項番29 | BJ23: 更新 | BO23: 井上 2016/3/8
BJ24: 追加
BJ25: 削除
C26: 仕変設変No-00009 | L26: 1.0 | P26: メッセージの統一に伴う修正 | AH26: メッセージID・出力先・メッセージテキスト・埋込情報を修正 | AZ26: チェック仕様 全般 | BJ26: 更新 | BO26: 松野 2016/3/31
BJ27: 追加
BJ28: 削除
C29: 仕変設変No-00018 | L29: 1.0 | P29: 社員基本情報の表示項目変更修正 | AH29: 社員基本情報に「生年月日」および「年齢」を表示する。 | AZ29: ・画面レイアウト ・画面項目仕様 | BJ29: 更新 | BO29: 藤橋 2016/3/31
BJ30: 追加
BJ31: 削除
C32: 仕変設変No-00060 | L32: 1.0 | P32: 家族情報のテーブル仕様変更および続柄コード仕様変更 | AH32: ①画面表示順のソート条件を記載する。 ②家族情報の連番化対応に伴い、更新仕様を修正する。 | AZ32: ①画面項目仕様 項番40 ①機能詳細：項番１（１）ウ ②テーブル更新仕様 テーブル名 ：入居申込家族（一時）項番03 | BJ32: 更新 | BO32: 松野 2016/5/12
BJ34: 追加
BJ35: 削除
C36: 仕変設変No-00021 | L36: 1.0 | P36: フロント１申請履歴表示に伴う変更 | AH36: ①申請取消時のデータ削除を、物理削除から論理削除に変更 ②申請取消時のToDo通知処理を追加 ③申請時のToDo通知時の更新ステータスを明記 | AZ36: ①機能詳細 １．（７）ア．（ア）ｂ．（ａ） テーブル更新仕様 更新（『申請取消』ボタン押下時） ②機能詳細 １．（７）ア．（ア）ａ． 機能詳細 １．（７）ア．（ア）ｂ．（ｂ） ③機能詳細 １．（６）ア．（ア）ｃ． 機能詳細 １．（６）ア．（ア）ｄ． | BJ36: 更新 | BO36: 藤橋 2016/4/7
BJ37: 追加
BJ38: 削除
C46: 仕変設変No-00079 | L46: 1.0 | P46: 組織マスタ、給与部課マスタのテーブル仕様変更に伴う修正 | AH46: 組織名、部課名を組織マスタ、部課マスタから、人事給与区分を条件に加えて取得するように変更する。 | AZ46: チェック仕様 項番02 画面項目仕様 項番19 機能詳細 項番１（１）ア（ア）ｃ | BJ46: 更新 | BO46: 井上 2016/4/30
BJ47: 追加
BJ48: 削除
C49: 仕変設変No-00115 | L49: 1.0 | P49: 社員情報テーブル、社員１日情報テーブルの変更 | AH49: 社宅申請時において、本務会社、本務組織に対応した本務社員区分、本務社員資格を利用するように修正する。 | AZ49: 機能詳細 項番１（１）ア（ア）ａ | BJ49: 更新 | BO49: 井上 2016/5/31
BJ50: 追加
BJ51: 削除
C54: 管理番号 | L54: 版 | P54: 変更理由 | AH54: 変更内容 | AZ54: 変更箇所 | BJ54: 変更区分 | BO54: 作成者 ・日付
C56: 仕変設変No-00116 | L56: 1.0 | P56: 人給システムとのインタフェース調整結果に伴う変更（共通マスタ関連） | AH56: 社員基本情報に表示する『組織名』の桁数を変更する。 『組織コード』10、12→8、『組織名』70→100 | AZ56: 画面レイアウト、画面項目仕様 『組織名』『組織コード』 | BJ56: 更新 | BO56: 井上 2016/6/15
BJ57: 追加
BJ58: 削除
C59: 仕変設変No-00128 | L59: 1.0 | P59: 利用者権限セキュリティの変更対応 | AH59: 代行申請時において、制度有無による対象社員の絞り込みを追加する。 | AZ59: 機能詳細 項番１（１）ア（ア） チェック仕様 １．項番13、 ２．項番06 補足説明 項番４ | BJ59: 更新 | BO59: 井上 2016/6/18
BJ60: 追加
...

Sheet 機能概要
A1: 機能概要 | P1: 業 務 | T1: =表紙!AC15 -> 社宅 | AH1: 機 能 | AL1: =表紙!AC23 -> 入居申請（人事） | AZ1: 作成者 | BC1: 白取 | BJ1: 作成日 | BM1: 42366
P2: 処 理 | T2: 社宅申込 | AH2: 処理種別 | AL2: オンライン | AZ2: 修正者 | BJ2: 修正日
B5: 機能概要 | AM5: データフロー
B6: 社員が、人事異動に伴う社宅への入居を希望するために、入居申請内容を登録する。 画面上から、世帯用社宅、単独身寮の区分、同居家族情報等を登録する。 | AM6: 「補足説明 １ データフロー図」参照
B22: 前提条件・制約事項・運用上の留意事項
B23: （１）申請状況が「審査中」「決裁中」の場合は申請できず、参照のみ可能とする。 （２）社員申請チェック情報に存在しない社員区分、社員資格の社員は、申請できない。（画面表示時にチェック） （３）社員が利用する場合、多言語対応を行う。
B37: セキュリティ要件
B38: 社員、または、各社厚生（審査者）が代行で、申請を行う。
C40: 利用権限 | I40: 社員 | Q40: 各社厚生
C41: ロール名 | I41: 個人申請業務 | Q41: 各社厚生（審査者）
C42: セキュリティ範囲 | I42: 利用者個人 | Q42: 会社＋組織

Sheet 画面遷移図
A1: 画面遷移図 | P1: 業 務 | T1: =表紙!AC15 -> 社宅 | AH1: 機 能 | AL1: =表紙!AC23 -> 入居申請（人事） | AZ1: 作成者 | BC1: =機能概要!BC1 -> 白取 | BJ1: 作成日 | BM1: =機能概要!BM1 -> 42366
P2: 処 理 | T2: =機能概要!T2 -> 社宅申込 | AH2: 処理種別 | AL2: =機能概要!AL2 -> オンライン | AZ2: 修正者 | BJ2: 修正日
B5: １．申請時、または、照会時
B34: ２．代行申請時

Sheet 画面レイアウト
A1: 画面レイアウト | P1: 業 務 | T1: =表紙!AC15 -> 社宅 | AH1: 機 能 | AL1: =表紙!AC23 -> 入居申請（人事） | AZ1: 作成者 | BC1: =機能概要!BC1 -> 白取 | BJ1: 作成日 | BM1: =機能概要!BM1 -> 42366
P2: 処 理 | T2: =機能概要!T2 -> 社宅申込 | AH2: 処理種別 | AL2: =機能概要!AL2 -> オンライン | AZ2: 修正者 | BC2: 杉山 | BJ2: 修正日 | BM2: 45609
C5: 画面名 | H5: 入居申請（人事） （１／３） | T5: 表示名 | V5: 入居申請（人事） | AH5: 画面ＩＤ | AM5: CHA10S01
C6: ・未申請のイメージ （「一時保存」も同様。）
C53: 画面名 | H53: 入居申請（人事） （２／３） | T53: 表示名 | V53: 入居申請（人事） | AH53: 画面ＩＤ | AM53: CHA10S01
C54: ・未申請のイメージ （「一時保存」も同様。）
C101: 画面名 | H101: 入居申請（人事） （２／３） | T101: 表示名 | V101: 入居申請（人事） | AH101: 画面ＩＤ | AM101: CHA10S01
C102: ・未申請のイメージ （「一時保存」も同様。）
C149: 画面名 | H149: 入居申請（人事） （１／３） | T149: 表示名 | V149: 入居申請（人事） | AH149: 画面ＩＤ | AM149: CHA10S01
C150: ・承認ワークフローの「未審査」時のイメージ （「審査ＯＫ」「決裁ＯＫ」「取消」「決裁ＮＧ」も同様。）
C197: 画面名 | H197: 入居申請（人事） （２／３） | T197: 表示名 | V197: 入居申請（人事） | AH197: 画面ＩＤ | AM197: CHA10S01
C198: ・承認ワークフローの「未審査」時のイメージ （「審査ＯＫ」「決裁ＯＫ」「取消」「決裁ＮＧ」も同様。）
C245: 画面名 | H245: 入居申請（人事） （３／３） | T245: 表示名 | V245: 入居申請（人事） | AH245: 画面ＩＤ | AM245: CHA10S01
C246: ・承認ワークフローの「未審査」時のイメージ （「審査ＯＫ」「決裁ＯＫ」「取消」「決裁ＮＧ」も同様。）
C293: 画面名 | H293: 入居申請（人事） （１／３） | T293: 表示名 | V293: 入居申請（人事） | AH293: 画面ＩＤ | AM293: CHA10S01
C294: ・承認ワークフローの「審査ＮＧ」時のイメージ
C341: 画面名 | H341: 入居申請（人事） （２／３） | T341: 表示名 | V341: 入居申請（人事） | AH341: 画面ＩＤ | AM341: CHA10S01
C342: ・承認ワークフローの「審査ＮＧ」時のイメージ
C389: 画面名 | H389: 入居申請（人事） （３／３） | T389: 表示名 | V389: 入居申請（人事） | AH389: 画面ＩＤ | AM389: CHA10S01
C390: ・承認ワークフローの「審査ＮＧ」時のイメージ
C437: 画面名 | H437: 入居申請（人事）検索 | T437: 表示名 | V437: 入居申請（人事）検索 | AH437: 画面ＩＤ | AM437: CHA10S02
C486: 画面名 | H486: 入居申請（人事）誓約書 | T486: 表示名 | V486: 入居申請（人事）誓約書 | AH486: 画面ＩＤ | AM486: CHA10S02

Sheet （不要になったら削除）画面レイアウト貼り付け用
B2: ＴＯＰ ＞ 入居申請（人事）
B4: 入居申請（人事）
D7: 社員基本情報
D9: 社員 | H9: 氏名コード | M9: XXXXXXX
H10: カナ氏名 | M10: XXXXXXXXXX XXXXXXXXXX
H11: 氏名 | M11: ＮＮＮＮＮ ＮＮＮＮＮ
H12: 生年月日 | M12: 9999/99/99 | Q12: 99歳 | V12: 性別 | Y12: 男性
H13: 職能資格 | M13: XXXX | Q13: ＮＮＮＮＮＮＮＮＮＮＮＮＮＮＮＮＮＮＮＮ
D14: 会社 | H14: 会社 | M14: XXXXXX | Q14: ＮＮＮＮＮＮＮＮＮＮＮＮＮＮＮＮＮＮＮＮＮＮＮＮＮＮＮＮＮＮＮＮＮＮＮＮ
H15: 組織 | M15: XXXXXXXX | Q15: ＮＮＮＮＮＮＮＮＮＮＮＮＮＮＮＮＮＮＮＮＮＮＮＮＮＮＮＮＮＮＮＮＮＮＮＮＮＮＮＮＮＮＮＮＮＮ
H16: 採用年月日 | M16: 9999/99/99 | Q16: 採用会社 | U16: ＮＮＮＮＮＮＮＮＮＮＮＮＮＮＮＮＮＮＮＮＮＮＮＮＮＮＮＮＮＮＮＮＮＮＮＮ
D18: 社宅申込（人事異動用）
D21: 発令年月日(必須) | L21: 2008/06/28 | R21: 任命年月日(必須) | X21: 2008/06/30 | AD21: 申込種別(必須) | AI21: 1:世帯
D22: 例)1900/04/01 | R22: 例)1900/04/01
D23: 入居希望時期 | L23: 003:その他 | R23: ７月より異動のため。
D24: 全角25文字以内
D25: 社宅入居状況(必須) | L25: 01:配偶者は現住居に継続入居し、その他の家族と同居（予定含む）のため世帯用社宅を申請
L27: 新職 | Z27: 現職
D29: 会社名(必須) | L29: 品川 | Z29: 品川
D30: 全角24文字以内
D31: 組織名(必須) | L31: 組織 | Z31: 組織
D32: 全角20文字以内
D33: 部課名 | L33: 部課 | Z33: 部課
D34: 全角20文字以内
D35: 出向先会社名 | L35: 五反田会社 | Z35: 池袋会社
D36: 全角24文字以内
D37: 所属電話番号(必須) | L37: 000-000-0000 | Z37: 111-111-1111
D38: 例)99-9999-9999
D39: 勤務地住所(必須) | L39: 五反田会社 | Z39: 五反田会社
D40: 例)●●県●●市●●町●-●
D41: 勤務地(ﾋﾞﾙ名等)(必須) | L41: 品川ビル | Z41: 池袋ビル
D42: 全角15文字以内
D43: 勤務先路線名･最寄駅(必須) | L43: 品川 | X43: 駅 | Z43: 品川 | AL43: 駅
D44: 全角20文字以内
D45: 連絡先電話番号(必須) | L45: 10-233-1615
D46: 例)99-9999-9999
D47: 連絡先メールアドレス | L47: sinsei@aaa
D48: 例)xxx@xx.xx
D50: 現在の居住状況
D51: 居住区分 | L51: 2:借家 | U51: 間取り(2LDK、3LDK) | AB51: 3K | AG51: 居住人数(本人含む)(必須) | AO51: 2 | AP51: 人
...

Sheet 画面項目仕様
A1: 画面項目仕様 | P1: 業 務 | T1: 社宅 | AH1: 機 能 | AL1: 入居申請（人事） | AZ1: 作成者 | BC1: 白取 | BJ1: 作成日 | BM1: 42366
P2: 処 理 | T2: 社宅申込 | AH2: 処理種別 | AL2: オンライン | AZ2: 修正者 | BC2: 杉山 | BJ2: 修正日 | BM2: 45125
C5: 画面名 | H5: 入居申請（人事） | AH5: 画面ＩＤ | AM5: CHA10S01
C7: 項番 | E7: 画面項目名 | O7: 入力形式 | U7: 属性 | X7: 桁数 | AB7: 共通チェックID | AG7: 入出力 | AJ7: 必須 | AL7: 初期値 | AQ7: 英語 対応 | AS7: 編集仕様／処理概要
X8: 最小 | Z8: 最大
C9: 01 | E9: 氏名コード | O9: テキスト（入力枠なし） | U9: X | X9: 0 | Z9: 7 | AG9: 出力 | AS9: 利用者が社員である場合、ログインユーザーの氏名コードを表示する。 利用者が各社厚生である場合、入居申請（人事）検索画面から引き継がれた氏名コードを表示する。
C12: 02 | E12: カナ氏名 | O12: テキスト（入力枠なし） | U12: X | X12: 0 | Z12: 49 | AG12: 出力 | AS12: 『氏名コード』に対応する［社員情報．氏名カナ］を表示する。
C14: 03 | E14: 氏名 | O14: テキスト（入力枠なし） | U14: Ｎ | X14: 0 | Z14: 61 | AG14: 出力 | AS14: 『氏名コード』に対応する［社員情報．氏名漢字］を表示する。
C16: 04 | E16: 生年月日 | O16: テキスト（入力枠なし） | U16: 日付 | X16: 0 | Z16: 10 | AG16: 出力 | AS16: 『氏名コード』に対応する［社員情報．生年月日］を表示する。
C18: 05 | E18: 年齢 | O18: テキスト（入力枠なし） | U18: X | X18: 0 | Z18: 3 | AG18: 出力 | AS18: 『生年月日』より、当年度末時点の年齢を算出して、表示する。（「年齢計算ニ関スル法律」に従う）
C20: 06 | E20: 性別 | O20: テキスト（入力枠なし） | U20: Ｎ | X20: 0 | Z20: 2 | AG20: 出力 | AQ20: ○ | AS20: 『氏名コード』に対応する［社員情報．性別コード］の名称を表示する。 （コード仕様の（業務共通）「性別コード」を参照）
C22: 07 | E22: 職能資格 | O22: テキスト（入力枠なし） | U22: X | X22: 0 | Z22: 4 | AG22: 出力 | AS22: 利用者が社員の場合、ラベルごと非表示とする。 利用者が各社厚生の場合、『氏名コード』に対応する［社員情報．本務社員資格］を表示する。
C24: 08 | E24: 職能資格名 | O24: テキスト（入力枠なし） | U24: Ｎ | X24: 0 | Z24: 20 | AG24: 出力 | AS24: 利用者が社員の場合、ラベルごと非表示とする。 利用者が各社厚生の場合、『氏名コード』に対応する［社員情報．本務職能資格名］を表示する。
C26: 09 | E26: 会社コード | O26: テキスト（入力枠なし） | U26: X | X26: 0 | Z26: 6 | AG26: 出力 | AS26: 『氏名コード』に対応する［社員情報．本務会社コード］を表示する。
C28: 10 | E28: 会社名 | O28: テキスト（入力枠なし） | U28: Ｎ | X28: 0 | Z28: 36 | AG28: 出力 | AS28: 『会社コード』に対応する［会社マスタ．会社正式名称（厚生）］を表示する。
C30: 11 | E30: 組織コード | O30: テキスト（入力枠なし） | U30: X | X30: 0 | Z30: 8 | AG30: 出力 | AS30: 『氏名コード』に対応する［社員情報．本務組織コード］を表示する。
C32: 12 | E32: 組織名 | O32: テキスト（入力枠なし） | U32: Ｎ | X32: 0 | Z32: 100 | AG32: 出力 | AS32: 『組織コード』に対応する［組織マスタ．組織名］を表示する。 （※人事給与区分は“0”（人事給与共用）または“1”（人事））
C34: 13 | E34: 採用年月日 | O34: テキスト（入力枠なし） | U34: 日付 | X34: 0 | Z34: 10 | AG34: 出力 | AS34: 『氏名コード』に対応する［社員情報．採用年月日］を表示する。
C36: 14 | E36: 採用会社 | O36: テキスト（入力枠なし） | U36: Ｎ | X36: 0 | Z36: 36 | AG36: 出力 | AS36: ［社員情報．出身会社コード］に対応する［会社マスタ．会社正式名称（厚生）］を表示する。
C38: 15 | E38: 申請状況 | O38: ラベル | AS38: 申請済み（※１）の場合、表示する。 未申請および一時保存（※２）の場合、非表示とする。 （「補足説明 ２．申請状況確認」を参照）
C41: 16 | F41: 現在の申請状況 | O41: テキスト（入力枠なし） | U41: Ｎ | X41: 0 | Z41: 15 | AG41: 出力 | AQ41: ○ | AS41: 『現在の申請状況』を表示する。（「補足説明 ２．申請状況確認」を参照） ※『現在の申請状況』を非表示とする場合、項目名を表示しない。
C43: 17 | F43: 申請年月日 | O43: テキスト（入力枠なし） | U43: 日付 | X43: 0 | Z43: 10 | AG43: 出力 | AS43: 申請済みの場合［入居申込（一時）．申請年月日］を表示する。
C45: 18 | F45: 審査者 | O45: テキスト（入力枠なし） | U45: Ｎ | X45: 0 | Z45: 61 | AG45: 出力 | AS45: 申請済みの場合［入居申込（一時）．審査者氏名コード］に対応する［社員情報．氏名漢字］を表示する。
C47: 19 | F47: 承認者 | O47: テキスト（入力枠なし） | U47: Ｎ | X47: 0 | Z47: 61 | AG47: 出力 | AS47: 申請済みの場合［入居申込（一時）．決裁者氏名コード］に対応する［社員情報．氏名漢字］を表示する。
E49: ※１：［入居申込（一時）．申請状況フラグ］が“1”（申請中）,“2”（審査中）,“3”（決裁中）,“X”（完了）,“9”（取消）の場合
E50: ※２：［入居申込（一時）］がレコード無し、あるいは［入居申込（一時）．申請状況フラグ］が“0”（一時保存中）の場合
C53: 項番 | E53: 画面項目名 | O53: 入力形式 | U53: 属性 | X53: 桁数 | AB53: 共通チェックID | AG53: 入出力 | AJ53: 必須 | AL53: 初期値 | AQ53: 英語 対応 | AS53: 編集仕様／処理概要
X54: 最小 | Z54: 最大
C55: 20 | E55: 発令年月日 | O55: テキストボックス | U55: 日付 | X55: 10 | Z55: 10 | AG55: 入力 | AJ55: ○ | AS55: （ユーザーが）発令年月日を入力、または、カレンダーダイアログで選択する。 一時保存または申請済みの場合［入居申込（一時）．発令年月日］を表示する。
C57: 21 | E57: 任命年月日 | O57: テキストボックス | U57: 日付 | X57: 10 | Z57: 10 | AG57: 入力 | AJ57: ○ | AS57: （ユーザーが）任命年月日を入力、または、カレンダーダイアログで選択する。 一時保存または申請済みの場合［入居申込（一時）．任命年月日］を表示する。
C59: 22 | E59: 申込種別 | O59: プルダウン | U59: - | X59: - | Z59: - | AG59: 入力 | AJ59: ○ | AQ59: ○ | AS59: （ユーザーが）申込種別を選択する。 一時保存または申請済みの場合［入居申込（一時）．申込種別コード］＋“:”＋「申込種別コードに対応する名称」を表示する。
C62: 23 | E62: 入居希望時期 | O62: プルダウン | U62: - | X62: - | Z62: - | AG62: 入力 | AQ62: ○ | AS62: （ユーザーが）入居希望時期を選択する。 一時保存または申請済みの場合［入居申込（一時）．入居希望時期コード］＋“:”＋「入居希望時期コードに対応する名称」を表示する。
C65: 24 | E65: 入居希望時期その他欄 | O65: テキストボックス | U65: Ｎ＋X | X65: 0 | Z65: 25 50 | AG65: 入力 | AS65: （ユーザーが）入居希望時期その他欄を入力する。
C67: 25 | E67: 社宅入居状況 | O67: プルダウン | U67: - | X67: - | Z67: - | AG67: 入力 | AJ67: ○ | AQ67: ○ | AS67: （ユーザーが）社宅入居状況を選択する。 一時保存または申請済みの場合［入居申込（一時）．社宅入居状況コード］＋“:”＋「社宅入居状況コードに対応する名称」を表示する。
C70: 26 | E70: 持家・単身赴任有無 | O70: プルダウン | U70: - | X70: - | Z70: - | AG70: 入力 | AJ70: ○ | AQ70: ○ | AS70: （ユーザーが）持家・単身赴任有無を選択する。 一時保存または申請済みの場合［入居申込（一時）．持家有無コード］＋“:”＋「持家有無コードに対応する名称」を表示する。（コード仕様の「持家単身有無コード」を参照）
C73: 27 | E73: 新職会社 | O73: テキストボックス | U73: Ｎ＋X | X73: 1 | Z73: 24 48 | AG73: 入力 | AJ73: ○ | AS73: （ユーザーが）新職会社を入力する。 一時保存または申請済みの場合［入居申込（一時）．新会社名］を表示する。
C75: 28 | E75: 現職会社 | O75: テキストボックス | U75: Ｎ＋X | X75: 1 | Z75: 24 48 | AG75: 入力 | AS75: （ユーザーが）現職会社を入力する。 一時保存または申請済みの場合［入居申込（一時）．旧会社名］を表示する。
C77: 29 | E77: 新職組織 | O77: テキストボックス | U77: Ｎ＋X | X77: 1 | Z77: 20 40 | AG77: 入力 | AJ77: ○ | AS77: （ユーザーが）新職組織を入力する。 一時保存または申請済みの場合［入居申込（一時）．新組織名］を表示する。
C79: 30 | E79: 現職組織 | O79: テキストボックス | U79: Ｎ＋X | X79: 0 | Z79: 20 40 | AG79: 入力 | AS79: （ユーザーが）現職組織を入力する。 一時保存または申請済みの場合［入居申込（一時）．旧組織名］を表示する。
C81: 31 | E81: 新職部課 | O81: テキストボックス | U81: Ｎ＋X | X81: 0 | Z81: 20 40 | AG81: 入力 | AS81: （ユーザーが）新職部課を入力する。 一時保存または申請済みの場合［入居申込（一時）．新部課名］を表示する。
...

Sheet 機能詳細 
A1: 機能詳細 | P1: 業 務 | T1: 社宅 | AH1: 機 能 | AL1: 入居申請（人事） | AZ1: 作成者 | BC1: 白取 | BJ1: 作成日 | BM1: 42366
P2: 処 理 | T2: 社宅申込 | AH2: 処理種別 | AL2: オンライン | AZ2: 修正者 | BC2: 杉山 | BJ2: 修正日 | BM2: 45125
A4: 入力 | N4: 処理 | BC4: イベントID | BH4: 出力
O6: １．入居申請（人事）画面
O8: （１）初期表示 | BC8: CHA10S0101
P9: 『氏名コード』をキーに［入居申込（一時）］［入居申込家族（一時）］を参照し、申請状況を確認する。
E10: ［入居申込（一時）］ | P10: （「補足説明 ２．申請状況確認」を参照）
E11: ［入居申込家族（一時）］ | P11: 申請状況が未申請の場合、社員の社員区分及び社員資格を確認し、申請可否チェックを行う。
E12: ［社員情報］
E13: ［家族情報］ | P13: ア．［入居申込（一時）］の申請状況確認を行う。
E14: ［社員区分申請チェック］ | P14: （ア）ログインユーザの利用権限が厚生担当の場合、対象社員のセキュリティチェックを行う。（「チェック仕様 項番13」を参照）
E15: ［社員資格申請チェック］
E16: ［会社マスタ］ | P16: （イ）申請状況が未申請の場合（「補足説明 ２．申請状況確認」を参照）
E17: ［組織マスタ］ | Q17: ａ．［社員情報．本務社員区分コード］及び［社員情報．本務社員資格］による申請可否チェックを行う。
E18: ［部課マスタ］ | R18: （「チェック仕様 項番01、02」を参照）
Q20: ｂ．現職情報の初期表示を行う。
Q21: （ａ）『氏名コード』をキーに［社員情報］より所属情報を取得する。
Q22: （ｂ）［社員情報．本務会社コード］をキーに現在有効な［会社マスタ．会社正式名称（厚生）］を取得し『現職会社』に表示する。
Q23: （ｃ）［社員情報．本務会社コード］［社員情報．本務組織コード］をキーに現在有効な［組織マスタ］
R24: （※人事給与区分が“0”（人事給与共用）または“1”（人事））を取得する。
R25: ・［組織マスタ．組織名］を『現職組織』に表示する。
R26: ・［組織マスタ．組織電話番号］を『連絡先電話番号』に表示する。
R27: ・［組織マスタ．組織住所１］［組織マスタ．組織住所２］を連結し、『現職勤務地住所』に表示する。
Q29: （ｄ）［社員情報．本務会社コード］［社員情報．本務組織コード］［社員情報．本務部課コード］をキーに現在有効な
R30: ［部課マスタ．部課名］（※人事給与区分が“0”（人事給与共用）または“1”（人事））を取得し、『現職部課』に表示する。
Q31: （ｅ）出向者([社員情報．社員状態コード]が“02”（02：在職出向者）または“03”（03：在籍出向者）の場合、
Q32: ［社員情報．出向先会社コード］をキーに現在有効な［会社マスタ．会社正式名称（厚生）］を取得し、
Q33: 『現職出向先会社』に表示する。
Q34: （ｆ）［社員情報．勤務先電話番号］を『現職所属電話番号』に表示する。
Q35: （ｇ）ビル名の取得
R36: ｉ．［社員情報．勤務先ビルコード］がNullの場合、［社員情報．勤務先ビル名］を『現職勤務地』に表示する。
R37: ⅱ．［社員情報．勤務先ビルコード］がNull以外の場合
S38: ［社員情報．本務会社コード］［社員情報．勤務先ビルコード］をキーに現在有効な［ビルマスタ．ビル名］を取得し、
S39: 『現職勤務地』に表示する。
P41: （ウ）［入居申込（一時）．申請状況フラグ］が“2”（審査中）“3”（決裁中）“9”（取消）“X”（完了）の場合、
Q42: 画面全体を入力不可とする。（「補足説明 ２．申請状況確認」を参照）
P44: イ．『氏名コード』をキーに［家族情報］を取得し、登録チェックを行う。（「チェック仕様 項番03」を参照）
P45: ウ．取得した［家族情報］を続柄コード、生年月日でソートして表示する。
O47: （２）『申込種別』の選択 | BC47: CHA10S0102
P48: ア．配偶者の有無をチェックを行う。（「チェック仕様 項番11～12」
...

Sheet チェック仕様
A1: チェック仕様 | P1: 業 務 | T1: 社宅 | AH1: 機 能 | AL1: 入居申請（人事） | AZ1: 作成者 | BC1: 白取 | BJ1: 作成日 | BM1: 42366
P2: 処 理 | T2: 社宅申込 | AH2: 処理種別 | AL2: オンライン | AZ2: 修正者 | BC2: 杉山 | BJ2: 修正日 | BM2: 45125
B5: １．入居申請（人事）画面
B6: 項番 | D6: チェック項目 | J6: チェック内容 | X6: チェック契機 | AD6: 出力先 | AH6: 重要度 | AL6: メッセージID | AQ6: メッセージテキスト | BH6: 埋込情報 | BR6: 英語 対応
B8: 01 | D8: 社員区分 | J8: 申請状況が未申請で、申請者が社宅入居申込（人事用）の申請を行える社員区分であること （該当社員の社員区分が、［社員区分申請チェック］に存在すること。） | X8: 画面表示時 | AD8: メッセージ出力エリア | AH8: エラー | AL8: CHA10E001 | AQ8: %1は社宅申込(人事異動用)の申請はできません。 | BH8: %1：社員区分名 | BR8: ○
B12: 02 | D12: 社員資格 | J12: 申請状況が未申請で、申請者が社宅入居申込（人事用）の申請を行える社員資格であること （該当社員の社員資格が、［社員資格申請チェック］に存在すること。） | X12: 画面表示時 | AD12: メッセージ出力エリア | AH12: エラー | AL12: CHA10E002 | AQ12: 社宅申込(人事異動用)の申請は認められていません。 | BR12: ○
B16: 03 | D16: 家族情報 | J16: 家族情報が登録されていること。 | X16: 『申込種別』変更時 『申請』ボタン押下時 | AD16: メッセージ出力エリア | AH16: エラー | AL16: CHA10E003 | AQ16: 家族情報が登録されていないため、世帯で使用する住居の選択はできません。 [申込種別]を変更するか、家族情報の登録後、再度申請を行ってください。 | BR16: ○
B21: 04 | D21: 家族情報の更新日時 | J21: ［家族情報］から更新日時が取得できること。 | X21: 『一時保存』ボタン押下時 『申請』ボタン押下時 | AD21: メッセージ出力エリア | AH21: エラー | AL21: CHA10E004 | AQ21: 家族情報が更新されているため社宅申込(人事異動用)の申請はできません。 社宅申込(人事異動用)の申請中に家族情報が変更された可能性があります。 再度、申請内容を入力しなおしてください。 | BR21: ○
B27: 05 | D27: 家族情報の更新日時 | J27: 申請内容の入力中に家族情報が更新されていないこと。 | X27: 『一時保存』ボタン押下時 『申請』ボタン押下時 | AD27: メッセージ出力エリア | AH27: エラー | AL27: CHA10E005 | AQ27: 家族情報が更新されているため社宅申込(人事異動用)の申請はできません。 社宅申込(人事異動用)の申請中に家族情報が変更された可能性があります。 再度、申請内容を入力しなおしてください。 | BR27: ○
B33: 06 | D33: 入居時期その他欄 | J33: 『入居時期その他欄』が表示されている場合、『入居時期その他欄』が入力されていること。 | X33: 『申請』ボタン押下時 | AD33: メッセージ出力エリア | AH33: エラー | AL33: CHA10E006 | AQ33: [入居希望時期その他欄]を入力してください。 | BR33: ○
B37: 07 | D37: 発令年月日 | J37: 『任命年月日』は『発令年月日』以降の日付であること。 | X37: 『申請』ボタン押下時 | AD37: メッセージ出力エリア | AH37: エラー | AL37: CHA10E007 | AQ37: [任命年月日]は[発令年月日]以降の日付を入力してください。 | BR37: ○
B41: 08 | D41: 同居別居 | J41: 同居予定者が選択されている場合、『同居別居』が設定されていること。 | X41: 『申請』ボタン押下時 | AD41: メッセージ出力エリア | AH41: エラー | AL41: CHA10E008 | AQ41: [同居別居]を選択してください。 | BR41: ○
B45: 09 | D45: 同居予定者 | J45: 同居家族が表示されている場合、『同居予定者』がいずれか一人が選択されていること。 | X45: 『申請』ボタン押下時 | AD45: メッセージ出力エリア | AH45: エラー | AL45: CHA10E009 | AQ45: [同居予定者]を選択してください。 | BR45: ○
B48: 10 | D48: カフェポイント | J48: カフェポイントが申請済であること。 | X48: 画面表示時 | AD48: 確認ダイアログ | AH48: メッセージ | AL48: CHA10E010 | AQ48: カフェポイントを申請してください。 | BR48: ○
B54: 項番 | D54: チェック項目 | J54: チェック内容 | X54: チェック契機 | AD54: 出力先 | AH54: 重要度 | AL54: メッセージID | AQ54: メッセージテキスト | BH54: 埋込情報 | BR54: 英語 対応
B56: 11 | D56: 配偶者有無 | J56: 申込種別が“2”（単身）である場合、配偶者が存在すること。 | X56: 『申請』ボタン押下時 『申込種別』の選択 | AD56: メッセージ出力エリア | AH56: エラー | AL56: CHA10E012 | AQ56: パートナーが存在しないため、[申込種別]を選択できません。 | BR56: ○
B59: 12 | J59: 申込種別が“3”（独身）である場合、配偶者が存在しないこと。 | X59: 『申請』ボタン押下時 『申込種別』の選択 | AD59: メッセージ出力エリア | AH59: エラー | AL59: CHA10E013 | AQ59: パートナーが存在するため、[申込種別]を選択できません。 | BR59: ○
B62: 13 | D62: 氏名コード | J62: 以下の検索条件にあてはまること。 ・ログインユーザーのセキュリティ範囲内 （「補足説明 項番４」参照） | X62: 画面表示時 | AD62: メッセージ出力エリア | AH62: エラー | AQ62: （メッセージテキストについては、「共通外部仕様 チェック仕様-２．検索画面共通」参照）
B65: 14 | D65: 承認ルート | J65: 承認ルートが取得できること。 | X65: 『申請』ボタン押下時 | AD65: メッセージ出力エリア | AH65: エラー | AL65: SSW00E027 | AQ65: 承認業務に必要な情報が設定されていないため申請を完了できません。[一時保存]ボタンを押して入力内容を一時保存後、ヘルプデスクにお問い合わせください。 | BR65: ○
B68: 15 | D68: 書類添付（登記簿謄本等） | J68: 『持家・単身赴任有無』が”0“（なし）以外である場合、『書類添付（登記簿謄本等）』にファイルが添付されていること。 | X68: 『申請』ボタン押下時 | AD68: メッセージ出力エリア | AH68: エラー | AL68: CHA10E015 | AQ68: [持家・単身赴任有無]が”あり“で選択されているため、[書類添付]でファイルを指定してください。 | BR68: 〇
AQ74: ※英語対応は「メッセージテキスト」および「埋込情報」箇所の対応を行う
B77: ２．入居申請（人事）検索画面
B78: 項番 | D78: チェック項目 | J78: チェック内容 | X78: チェック契機 | AD78: 出力先 | AH78: 重要度 | AL78: メッセージID | AQ78: メッセージテキスト | BH78: 埋込情報 | BR78: 英語 対応
B80: 01 | D80: 会社コード | J80: 会社コードが［会社マスタ］に存在すること。 | X80: 『検索』ボタン押下時 | AD80: メッセージ出力エリア | AH80: エラー | AL80: CH000E011 | AQ80: %1が存在しません。 | BH80: %1：“[会社コード]”
B83: 02 | D83: 組織コード | J83: 組織コードが［組織マスタ］に存在すること。 （人事給与区分は“0”（人事給与共用）または “1”（人事）） | X83: 『検索』ボタン押下時 | AD83: メッセージ出力エリア | AH83: エラー | AL83: CH000E011 | AQ83: %1が存在しません。 | BH83: %1：“[組織コード]”
B86: 03 | D86: 氏名コード | J86: 氏名コードが［社員情報］に存在すること。 | X86: 『検索』ボタン押下時 | AD86: メッセージ出力エリア | AH86: エラー | AL86: CH000E011 | AQ86: %1が存在しません。 | BH86: %1：“[氏名コード]”
B89: 04 | J89: 氏名コードが全て数字で入力されていること。 | X89: 『検索』ボタン押下時 | AD89: 入力フィールド下部 | AH89: エラー | AQ89: （メッセージテキストについては、「共通外部仕様 チェック仕様-バリデーションチェック」参照）
B92: 05 | J92: チェックデジットが入力されていること。 | X92: 『検索』ボタン押下時 | AD92: 入力フィールド下部 | AH92: エラー | AQ92: （メッセージテキストについては、「共通外部仕様 チェック仕様-バリデーションチェック」参照）
B95: 06 | D95: 検索条件 | J95: 以下の検索条件にあてはまること。 ・ログインユーザーのセキュリティ範囲内 （「補足説明 項番４」参照） ※氏名、氏名カナは、部分一致で検索すること | X95: 『検索』ボタン押下時 | AD95: メッセージ出力エリア | AH95: エラー | AQ95: （メッセージテキストについては、「共通外部仕様 チェック仕様-２．検索画面共通」参照）

Sheet 帳票レイアウト
A1: 帳票レイアウト | P1: 業 務 | T1: =表紙!AC15 -> 社宅 | AH1: 機 能 | AL1: =表紙!AC23 -> 入居申請（人事） | AZ1: 作成者 | BC1: =機能概要!BC1 -> 白取 | BJ1: 作成日 | BM1: =機能概要!BM1 -> 42366
P2: 処 理 | T2: =機能概要!T2 -> 社宅申込 | AH2: 処理種別 | AL2: =機能概要!AL2 -> オンライン | AZ2: 修正者 | BJ2: 修正日
C5: 帳票名 | AH5: 帳票ＩＤ

Sheet 帳票項目仕様
A1: 帳票項目仕様 | P1: 業 務 | T1: =表紙!AC15 -> 社宅 | AH1: 機 能 | AL1: =表紙!AC23 -> 入居申請（人事） | AZ1: 作成者 | BC1: =機能概要!BC1 -> 白取 | BJ1: 作成日 | BM1: =機能概要!BM1 -> 42366
P2: 処 理 | T2: =機能概要!T2 -> 社宅申込 | AH2: 処理種別 | AL2: =機能概要!AL2 -> オンライン | AZ2: 修正者 | BJ2: 修正日
C5: 帳票名 | AH5: 帳票ＩＤ
C7: 一覧／ 単票 | G7: 用紙 サイズ | L7: ファイル名
C11: 出力対象条件 | AO11: ソート順 | BD11: データレコード部最大行数
C15: 改ページ条件 | U15: 出力形式 | AD15: その他
C19: 項番 | F19: 項目名 | W19: 編集 | AC19: フォント | AN19: 文字配置 | AR19: 編集仕様
W20: 属性 | Z20: 桁数 | AC20: 形式 | AK20: サイズ
C21: 01
C23: 02
C25: 03
C27: 04
C29: 05
C31: 06
C33: 07
C35: 08
C37: 09
C39: 10
C41: 11
C43: 12
... C47: 14

Sheet 入力ファイル項目仕様
A1: 入力ファイル項目仕様 | P1: 業 務 | T1: =表紙!AC15 -> 社宅 | AH1: 機 能 | AL1: =表紙!AC23 -> 入居申請（人事） | AZ1: 作成者 | BC1: =機能概要!BC1 -> 白取 | BJ1: 作成日 | BM1: =機能概要!BM1 -> 42366
P2: 処 理 | T2: =機能概要!T2 -> 社宅申込 | AH2: 処理種別 | AL2: =機能概要!AL2 -> オンライン | AZ2: 修正者 | BJ2: 修正日
C5: 日本語ファイル名 | AH5: ファイルＩＤ
C7: ファイル形式 | L7: レコード形式 | Q7: レコード長 | V7: ファイル名
C11: 入力ファイル説明
C15: その他
C20: 項番 | F20: 項目名 | T20: 編集 | Z20: 項目説明
T21: 属性 | W21: 桁数
C22: 01
C24: 02
C26: 03
C28: 04

Sheet 出力ファイル項目仕様
A1: 出力ファイル項目仕様 | P1: 業 務 | T1: =表紙!AC15 -> 社宅 | AH1: 機 能 | AL1: =表紙!AC23 -> 入居申請（人事） | AZ1: 作成者 | BC1: =機能概要!BC1 -> 白取 | BJ1: 作成日 | BM1: =機能概要!BM1 -> 42366
P2: 処 理 | T2: =機能概要!T2 -> 社宅申込 | AH2: 処理種別 | AL2: =機能概要!AL2 -> オンライン | AZ2: 修正者 | BJ2: 修正日
C5: 日本語ファイル名 | AH5: ファイルＩＤ
C7: ファイル形式 | L7: レコード形式 | Q7: レコード長 | V7: ファイル名
C11: 出力対象条件 | AT11: ソート順
C15: その他
C20: 項番 | F20: 項目名 | T20: 編集 | Z20: 項目説明
T21: 属性 | W21: 桁数
C22: 01
C24: 02
C26: 03
C28: 04

Sheet テーブル更新仕様
A1: テーブル更新仕様 | P1: 業 務 | T1: =表紙!AC15 -> 社宅 | AH1: 機 能 | AL1: =表紙!AC23 -> 入居申請（人事） | AZ1: 作成者 | BC1: =機能概要!BC1 -> 白取 | BJ1: 作成日 | BM1: =機能概要!BM1 -> 42366
P2: 処 理 | T2: =機能概要!T2 -> 社宅申込 | AH2: 処理種別 | AL2: =機能概要!AL2 -> オンライン | AZ2: 修正者 | BC2: 杉山 | BJ2: 修正日 | BM2: 45125
B5: テーブル名 ：入居申込（一時）
B6: 処理パターン：追加・更新（『一時保存』または『申請』ボタン押下時）
C8: 項番 | F8: 項目名 | T8: 編集仕様
C10: 01 | F10: 氏名コード | T10: 『氏名コード』を設定する。（キー項目）
C12: 02 | F12: 申請ID | T12: 追加時：『一時保存』の場合、“TEMP000000000002”を設定する。 追加時：『申請』の場合、新規採番（採番方法はフロント業務の関数を利用する。）したIDを設定する。 更新時：『申請』かつ、未採番の場合（申請IDが“TEMP000000000002”の場合）は、新規採番したIDを設定する。 更新時：上記以外の場合、更新しない。（キー項目）
C16: 03 | F16: 申請状況フラグ | T16: 『一時保存』の場合は、“0”（一時保存中）を設定する。 『申請』の場合は、“2”（審査中）を設定する。
C18: 04 | F18: 申請年月日 | T18: 『一時保存』の場合は、NULLを設定する。 『申請』の場合は、業務日付を設定する。
C20: 05 | F20: 審査年月日 | T20: 追加時：NULLを設定する。 更新時：『申請』の場合は、NULLを設定する。 更新時：『一時保存』の場合は、更新しない。
C23: 06 | F23: 審査者氏名コード | T23: 追加時：“”を設定する。 更新時：『申請』の場合は、“”を設定する。 更新時：『一時保存』の場合は、更新しない。
C26: 07 | F26: 決裁年月日 | T26: 追加時：NULLを設定する。 更新時：更新しない。
C28: 08 | F28: 決裁者氏名コード | T28: 追加時：“”を設定する。 更新時：更新しない。
C30: 09 | F30: 代行入力者氏名コード | T30: （利用者が各社厚生である場合）代行入力者の氏名コードを設定する。
C32: 10 | F32: NG有無フラグ | T32: “1”（ＯＫ）を設定する。
C34: 11 | F34: NG理由 | T34: 追加時：“”を設定する。 更新時：更新しない
... C89: 36 | F89: 新所属電話番号 | T89: 『新職所属電話番号』を設定する。
C91: 37 | F91: 新勤務地住所 | T91: 『新職勤務地住所』を設定する。
C93: 38 | F93: 新勤務地（ビル名等） | T93: 『新職勤務地』を設定する。
C95: 39 | F95: 新勤務先最寄駅 | T95: 『新職勤務先最寄駅』を設定する。
C97: 40 | F97: 旧会社名 | T97: 『現職会社』を設定する。
C102: 項番 | F102: 項目名 | T102: 編集仕様
C104: 41 | F104: 旧組織名 | T104: 『現職組織』を設定する。
C106: 42 | F106: 旧部課名 | T106: 『現職部課』を設定する。
C108: 43 | F108: 旧出向会社名 | T108: 『現職出向先会社』を設定する。
C110: 44 | F110: 旧所属電話番号 | T110: 『現職所属電話番号』を設定する。
C112: 45 | F112: 旧勤務地住所 | T112: 『現職勤務地住所』を設定する。
C114: 46 | F114: 旧勤務地（ビル名等） | T114: 『現職勤務地』を設定する。
C116: 47 | F116: 旧勤務先最寄駅 | T116: 『現職勤務先最寄駅』を設定する。
C118: 48 | F118: 連絡先電話番号 | T118: 『連絡先電話番号』を設定する。
C120: 49 | F120: 入居希望時期コード | T120: 『入居希望時期』を設定する。
C122: 50 | F122: 入居希望時期その他 | T122: 『入居希望時期その他欄』を設定する。
C124: 51 | F124: 社宅説明事項 | T124: 『特に考慮すべき事項等』を設定する。
C126: 52 | F126: 返信先メールアドレス（審査者） | T126: “”を設定する。
... C146: 62 | F146: 最終更新日時 | T146: システム日時を設定する。
B149: テーブル名 ：入居申込家族（一時）
B150: 処理パターン：追加・更新（『一時保存』または『申請』ボタン押下時）
C152: 項番 | F152: 項目名 | T152: 編集仕様
C154: 01 | F154: 氏名コード | T154: ［入居申込（一時）．氏名コード］を設定する。（キー項目）
C156: 02 | F156: 申請ID | T156: 追加時：［入居申込（一時）．申請ID］を設定する。（キー項目） 更新時：更新しない。
...

Sheet 補足説明
A1: 補足説明 | P1: 業 務 | T1: =表紙!AC15 -> 社宅 | AH1: 機 能 | AL1: =表紙!AC23 -> 入居申請（人事） | AZ1: 作成者 | BC1: =機能概要!BC1 -> 白取 | BJ1: 作成日 | BM1: =機能概要!BM1 -> 42366
P2: 処 理 | T2: =機能概要!T2 -> 社宅申込 | AH2: 処理種別 | AL2: =機能概要!AL2 -> オンライン | AZ2: 修正者 | BC2: 井上 | BJ2: 修正日 | BM2: 42539
B5: １．データフロー図
B53: ２．申請状況確認
B54: （１）［入居申込（一時）．申請種別コード］が“2”（人事申込）のレコードが以下の条件の場合に『申請状況』および『現在の申請状況』を判断する。
C56: イベント | Q56: ［入居申込（一時）］の設定値
C57: 入居申請 | J57: 承認ワークフロー | Q57: ［申請状況フラグ］ | X57: ［申請年月日］ | AE57: ［審査年月日］ | AL57: ［決裁年月日］ | AS57: ［NG有無フラグ］ | AZ57: 『申請状況』 | BG57: 『現在の申請状況』
C58: 該当レコード無し | Q58: － | X58: － | AE58: － | AL58: － | AS58: － | AZ58: 未申請 | BG58: 非表示
C60: 一時保存 | Q60: “0”（一時保存中） | X60: － | AE60: － | AL60: － | AS60: － | AZ60: 一時保存中 | BG60: 非表示
C62: 申請 | J62: 未審査 | Q62: “2”（審査中） | X62: 申請時のシステム日付 | AE62: － | AL62: － | AS62: － | AZ62: 審査中 | BG62: 審査中
J64: 審査ＯＫ | Q64: “3”（決裁中） | X64: － | AE64: 審査時のシステム日付 | AL64: － | AS64: “1”（ＯＫ） | AZ64: 決裁中 | BG64: 決裁中
J66: 決裁ＯＫ | Q66: “X”（完了） | X66: － | AE66: － | AL66: 決裁時のシステム日付 | AS66: “1”（ＯＫ） | AZ66: 未申請（※１） | BG66: 完了
J69: 取消 | Q69: “9”（取消） | X69: － | AE69: － | AL69: － | AS69: “1”（ＯＫ） | AZ69: 未申請（※１） | BG69: 取消
J71: 審査ＮＧ | Q71: “1”（申請中） | X71: － | AE71: 否決時のシステム日付 | AL71: － | AS71: “9”（ＮＧ） | AZ71: 申請中 | BG71: 非表示
J73: 決裁ＮＧ | Q73: “2”（審査中） | X73: － | AE73: － | AL73: 否決時のシステム日付 | AS73: “9”（ＮＧ） | AZ73: 審査中 | BG73: 審査中
D75: ※１：申請履歴機能から遷移した場合のみ、「氏名コード」「申請ＩＤ」をキーにして、［入居申込（一時）］のデータを表示する。申請履歴機能以外から遷移した場合は、未申請として、新たな入居申込を可能とする。
B101: ３．画面表示制御
B102: （１）申込種別
C103: 申込種別が以下の場合に、同居家族欄の表示・非表示を制御する。
C105: 申込種別コード | J105: 同居家族欄の表示制御
C106: “1”（世帯） | J106: 表示
C107: “2”（単身） | J107: 非表示
C108: “3”（独身） | J108: 非表示
B110: （２）入居希望時期
C111: 入居希望時期が以下の場合に、入居希望時期その他欄の表示・非表示を制御する。
C113: 入居希望時期コード | J113: 入居希望時期その他欄の表示制御
C114: “001”（即入居） | J114: 非表示
C115: “002”（学期の区切り） | J115: 非表示
C116: “003”（その他） | J116: 表示
B118: ４．代行申請時のセキュリティ範囲の特定方法について
C119: 代行申請時におけるログインユーザのセキュリティ範囲の特定方法を以下に記す。
B121: （１）運用グループ処理範囲による会社コード、または会社コード＋組織コードの絞り込み
C122: ア．ログインユーザに紐づく運用グループ処理範囲を取得し、「社宅＿厚生」ロール区分に該当する「会社コード」または「会社コード」＋「組織コード」を取得する。
C123: イ．上記４（１）アで取得した運用グループ処理範囲と、［社員情報．本務会社コード］（または［社員情報．本務会社コード］［社員情報．本務組織コード］）を紐付けて、対象社員を絞り込む。
B125: （２）制度有無による絞り込み
C126: ア．［制度適用会社］テーブルより、［制度適用会社．制度区分］が“03”（社宅）に該当する「会社コード」「社員区分」を取得し、［社員情報．本務会社コード］［社員情報．本務社員区分コード］と紐付けて、対象社員を絞り込む。
B128: （３）厚生系対象社員の絞り込み
C129: ア．［社員情報．情報取込区分］が“1”（人事給与）、“2”（アップデートファイル）、［社員情報．一般スタッフ区分］が“1”（一般）を条件にして、対象社員を絞り込む
